Workbook

Sheet Overview
A2: Worksheet | B2: Content
A3: Indicator list-QQC structural | B3: Definition and descripton of indicators
A4: 1-SAMPLE | B4: Overview of planned and achieved sample
A5: 2-QQM_SUMMARY_SHEET | B5: Summary overview of the QQM indicators, per domain and province
A6: 3-QQM_BY ROUND | B6: Provincial QQM structural, outcome and content quality scores, per round and province
A7: Annex 1a - QQC_Structural_PROV | B7: Detailed overview of the scores for QQC structural quality, per province
A8: Annex1b-QQC_Structural_FAC | B8: Detailed overview of the scores for QQC structural quality, per health facility
A9: Annex1c-QQC_Tracerdrugs_PROV | B9: Detailed overview of availability of tracer drugs, per province
A10: Annex2a-QQM_EXIT&VIGNETTES_PROV | B10: Detailed overview of the scores for QQM outcome quality (exit interviews) and content of care(vignettes) indicators, per province
A11: Annex 2b-QQC_EXIT&VIGNETTES_FAC | B11: Detailed overview of the scores for QQM outcome quality (exit interviews) and content of care(vignettes) indicators, per health facility
A12: Annex 3a-HEALTH WORKERS - PROV | B12: Detailed overview of the scores for non-QQM indicators on Staffing (Salary payment, Health staff availability, GBV training, HW satisfaction), per province
A13: Annex 3b-HEALTH WORKERS - FAC | B13: Detailed overview of the scores for non-QQM indicators on Staffing (Salary payment, Health staff availability, GBV training, HW satisfaction), per health facility
... A15: Annex 4b-MSS - FAC'!A1 | B15: Detailed overview of the scores for Minimum Standard of Services for health facilities not covered by QQM ( i.e SHC, RH/PH), per health facility

Sheet Indicator list
A1: Overview of indicators by assessment
A2: # indicator | B2: Indicator Name | C2: Sub-indicator / Description | D2: Max Points (YES) | E2: Max Points (from DO files) | F2: Applicable at HFs
A3: QQM Structural Quality - Domain 1: General Management | D3: =SUM(D4:D16) -> 14
A4: SQ 1.1 | B4: Presence of map of health facility catchment area | C4: A visually represented health map is displayed on the notice board of a health facility. The map includes population data, details of other health facilities in the area, villages, main roads, natural barriers, special points and distance (in kms) and a legend/key showing specific age group population adjusted yearly (<1, <5, WCBA). | D4: 0.5 | E4: 0.5 | F4: BHC, CHC, DH
A5: SQ 1.2 | B5: Proper filing system | C5: 1.2.1 In a filing cabinet/shelf/cupboard, in the designated service, and accessible by the officer on duty (except individual staff files) | D5: 0.5 | E5: 0.5 | F5: BHC, CHC, DH
C6: 1.2.2 Minimum documents to be filled in the Administrative office (i) HMIS and (ii) clinic visit book | D6: 0.5 | E6: 0.5 | F6: BHC, CHC, DH
C7: 1.2.3 (iii)Attendance sheet and (iv) monthly, quarterly and annual activity plans and (v) staff meeting notebook | D7: 0.5 | E7: 0.5 | F7: BHC, CHC, DH
C8: 1.2.4 (vi) Financial file and (vii) community contribution register | D8: 0.5 | E8: 0.5 | F8: BHC, CHC, DH
C9: 1.2.5 Minimum documents to be filled include CHS room: (ix) CHW supervision visit book; (x) clinic health committee meeting minutes | D9: 0.5 | E9: 0.5 | F9: BHC, CHC, DH
A10: SQ 1.3 | B10: Staff duty roster | C10: The staff duty roster is regularly updated and prominently displayed to both staff and patients. The roster includes the schedule for the current month, the assigned duties of each staff member and the phone numbers of on-duty staff. | D10: 1 | E10: 1 | F10: BHC, CHC, DH
A11: SQ 1.4 | B11: Technical meetings | C11: Technical Meetings (Management Committee Meetings & Clinical Staff Meetings) are scheduled on a monthly basis. QI committee meetings can alternate with clinical staff meetings; with 2 weeks between meetings. Minutes are taken during each meeting and include the date of the meeting, progress updates on the implementation of previous recommendations or actions, a list of new recommendations or decisions, and the chairman's signature. Records include three complete Clinical Staff Meetings and one quarterly Management Committee Meeting with detailed minutes. | D11: 4 | E11: 4 | F11: BHC, CHC, DH
A12: SQ 1.5 | B12: Standard referral sheets | C12: At least 10 (empty) standard referral sheets are present during the evaluation | D12: 1 | E12: 1 | F12: BHC, CHC, DH
A13: SQ 1.6 | B13: Availability of dedicated mobile phone for communication between health facility and general hospital | C13: A functional and charged mobile phone with a minimum call credit of AFS200. At minimum, the phone must store contact details of the Medical Director of the District Hospital, health facility staff, other Health Facility in-charges within the district, district health department, and the SP contact. | D13: 1 | E13: 1 | F13: BHC, CHC, DH
A14: SQ 1.7 | B14: HMIS reports (sent to SP offices and MoPH) | C14: The transmission of HMIS reports occurs on a monthly basis, and a signed receipt of acknowledgement, both from the SP provincial offices and the MoPH is available. | D14: 1 | E14: 1 | F14: BHC, CHC, DH
A15: SQ 1.8 | B15: HMIS reports (assessed concerning priority problems) | C15: Each quarter, four priority health problems are monitored and the data in the report has been updated until the month preceding the supervisor's visit. Additionally, the report includes a graphical representation of the health facility's quality score (presented in an "all or nothing" format). This score is derived from a monthly summary of the health problem classifications recorded in the General register at the end of each month. | D15: 1 | E15: 1 | F15: BHC, CHC, DH
A16: SQ 1.9 | B16: Health Shura meetings | C16: Health Shura meetings are conducted on a monthly basis and meeting minutes are available. The monthly minutes include (i) the date of the meeting; (ii) a signed list of participants; (iii) follow-up of decisions taken during the previous meeting; (iv) a list of developed recommendations or decisions made; (v) signature of the chairman. | D16: 2 | E16: 2 | F16: BHC, CHC, DH
A17: QQM Structural Quality - Domain 2: Hygiene | D17: =SUM(D18:D40) -> 34
A18: SQ 2.1 | B18: Fence health facility available and well-maintained | C18: There is fencing or a wall (at least 1.5m in height) in good condition (no cracks) around the area of the health facility that can be closed at night (except riverine areas) | D18: 1 | E18: 1 | F18: BHC, CHC, DH
A19: SQ 2.2 | B19: Garbage bin | C19: The courtyard has a garbage bin with a lid that is easily accessible to clients, and it is not full at the time of the evaluation. | D19: 1 | E19: 1 | F19: BHC, CHC, DH
A20: SQ 2.3 | B20: Latrines/toilets | C20: 2.3.1 At least four water closet functional latrines/toilets (either the flushable squatting closet or the sitting closet) two for staff: Male and female, two for patients: Male and female. Toilets have a written and a pictorial sign. | D20: 1 | E20: 1 | F20: BHC, CHC, DH
C21: 2.3.2 Floor without fissures | D21: 0.5 | E21: 0.5 | F21: BHC, CHC, DH
C22: 2.3.3 Recently cleaned without visible fecal matter | D22: 0.5 | E22: 0.5 | F22: BHC, CHC, DH
C23: 2.3.4 Door lockable from the inside, ceiling and super structure with roofing, without flies and no smell | D23: 0.5 | E23: 0.5 | F23: BHC, CHC, DH
C24: 2.3.5 Hand hygiene/ sinks are located at the toilets AND running water is available (either sourced from a container or from piped water supply) AND soap or liquid soap, or detergent available at the sink. | D24: 0.5 | E24: 0.5 | F24: BHC, CHC, DH
A25: SQ 2.4 | B25: Showers | C25: 2.4.1 At least two bathing facilities; one for men one for women (with floor without fissures, Door lockable from the inside, super structure with roofing) (in case of BHC one bathing facility (for women only); in case of CHC at least two; one for men and one for women) | D25: 1 | E25: 1 | F25: BHC, CHC, DH
C26: 2.4.2 Bathing facility with running water, or container with at the least 20 L of water | D26: 0.5 | E26: 0.5 | F26: BHC, CHC, DH
C27: 2.4.3 Evacuation of the waste water in a sanitation pit | D27: 0.5 | E27: 0.5 | F27: BHC, CHC, DH
A28: SQ 2.5 | B28: Waste pit | C28: 2.5.1 Waste disposal pit minimum 4 meters deep, lined with clay, concrete or brick or plastic, it is fenced and has a bright flag | D28: 12 | E28: 12 | F28: BHC, CHC, DH
C29: 2.5.2 The waste pit is a minimum of 15 meters from the health facility, minimum of 50 meters from a household, and 100 meters from a water source except in cases where the available surface area does not allow for these distances | F29: BHC, CHC, DH
C30: 2.5.3 Health Care Waste is not visible (covered by at the least 10 cm of soil or lime) | F30: BHC, CHC, DH
C31: 2.5.4 The health facility maintains a register indicating the date of the creation of the pit(s), and the location (s) | F31: BHC, CHC, DH
A32: SQ 2.6 | B32: Courtyard clean | D32: 1 | E32: 1 | F32: BHC, CHC, DH
A33: SQ 2.7 | B33: Sterilization | C33: 2.7.1 Sterilizer functional (eg Autoclave) | D33: 3 | E33: 3 | F33: BHC, CHC, DH
C34: 2.7.2 Sterilization protocol available and followed (medical personnel present can explain the protocol or demonstrate the process). When explaining the staff should at the least cover: (i) how items are arranged/packed; (ii) explain sterilization time for packed and unpacked items, and (iii) how to unload the items from the sterilizer | F34: BHC, CHC, DH
A35: SQ 2.8 | B35: Hygienic conditions assured during wound dressing and injections | C35: 2.8 1 Yellow and Red Bins for medical waste with lid and foot pedal, lined with bag and not full | D35: 2 | E35: 2 | F35: BHC, CHC, DH
C36: 2.8.2 Security box for needles well positioned, and used (and not full) | F36: BHC, CHC, DH
C37: 2.8.3 Needle cutter available and used | F37: BHC, CHC, DH
C38: 2.8.4 Container/bowl with lid containing disinfectant used for putting used instruments | F38: BHC, CHC, DH
A39: SQ 2.9 | B39: Disposal of Health Care Waste | C39: Waste is segregated into three bin categories for proper disposal in accordance with national norms. None of the bins should be full or over-flowing. i) Non-contaminated waste, which includes general or municipal waste such as food items, carton boxes, wrappings, and garbage are placed in lined Black Bins equipped with lids and foot pedals and the waste bin is not full; and, ii) Contaminated health care waste, which includes infectious hazardous materials like used medical equipment, linens, gauze, syringes, catheter, iv cannula, gloves, serum bottles, and more are placed in cellophane-lined Yellow Bins with lids and foot pedals; and, iii) Organic health care waste including body parts, placenta, removed teeth, body fluids, suction machine secretions, expired blood, and other biohazardous materials are placed in cellophane-lined Red Bins with lids and foot pedals; and, iv) Availability of proper protective gear, including caps, masks, gumboots or enclosed shoes, plastic aprons, and thick plastic/rubber gloves. | D39: 6 | E39: 6 | F39: BHC, CHC, DH
A40: SQ 2.1 | B40: COVID-19 prevention | C40: 2.10.1 i) Masks are available and used by staff ii) Alcohol handwashing solution is available for staff and patients in at the least (i) OPD and (ii) MCH section and (iii) EPI iii) COVID-19 prevention posters visible for patients in waiting room for OPD, and consultation room, and MCH section, and EPI section | D40: 3 | E40: 3 | F40: BHC, CHC, DH
...

Sheet 1-SAMPLE
A1: QQC | S1: FV
A2: Achieved sample | I2: Planned sample | N2: % Achieved | S2: Achieved sample | AF2: Planned sample | AK2: % Achieved
A3: Province | B3: SP (October-December 2024) | C3: SP (October-December 2024) | D3: BPHS facilities | F3: EPHS Facilities | G3: Total Surveyed | I3: Province | J3: BPHS facilities | K3: EPHS Facilities | L3: Total Sampled | N3: Province | O3: BPHS facilities | P3: EPHS Facilities | Q3: Total Sampled | S3: Province | T3: SP (October-December 2024) | U3: SP (October-December 2024) | V3: BPHS facilities | Z3: EPHS Facilities | AD3: Total Surveyed | AF3: Province | AG3: BPHS facilities | AH3: EPHS Facilities | AI3: Total Sampled | AK3: Province | AL3: BPHS facilities | AM3: EPHS Facilities | AN3: Total Sampled
D4: CHC | E4: BHC | F4: DH | V4: CHC | W4: BHC | X4: SHC | Y4: Total BPHS | Z4: DH | AA4: PH | AB4: RH | AC4: Total EPHS
A5: province | B5: sp_old | C5: sp | D5: n2 | E5: n1 | F5: n4 | G5: total_surveyed | H5: blank1 | I5: province1 | J5: planned_bphs | K5: planned_ephs | L5: total_planned | M5: blank2 | N5: province2 | O5: achieved_bphs | P5: achieved_ephs | Q5: achieved_total | S5: province | T5: sp_old | U5: sp | V5: n2 | W5: n1 | X5: n3 | Y5: bphs_total | Z5: n4 | AA5: n5 | AB5: n7 | AC5: ephs_total | AD5: total_surveyed | AE5: blank1 | AF5: province1 | AG5: planned_bphs | AH5: planned_ephs | AI5: total_planned | AJ5: blank2 | AK5: province2 | AL5: achieved_bphs | AM5: achieved_ephs | AN5: achieved_total
A6: Overall | D6: 47 | E6: 102 | F6: 23 | G6: 172 | I6: Overall | J6: 149 | K6: 23 | L6: 172 | N6: Overall | O6: 1 | P6: 1 | Q6: 1 | S6: Overall | V6: 47 | W6: 102 | X6: 141 | Y6: 290 | Z6: 23 | AA6: 3 | AB6: 0 | AC6: 26 | AD6: 316 | AF6: Overall | AG6: 290 | AH6: 26 | AI6: 316 | AK6: Overall | AL6: 1 | AM6: 1 | AN6: 1
A7: Badakhshan | B7: AKF | C7: AKF | D7: 2 | E7: 4 | F7: 0 | G7: 6 | I7: Badakhshan | J7: 6 | K7: 0 | L7: 6 | N7: Badakhshan | O7: 1 | Q7: 1 | S7: Badakhshan | T7: AKF | U7: AKF | V7: 2 | W7: 4 | X7: 9 | Y7: 15 | Z7: 0 | AA7: 1 | AB7: 0 | AC7: 1 | AD7: 16 | AF7: Badakhshan | AG7: 15 | AH7: 1 | AI7: 16 | AK7: Badakhshan | AL7: 1 | AM7: 1 | AN7: 1
A8: Baghlan | B8: AKF | C8: AKF | D8: 2 | E8: 3 | F8: 1 | G8: 6 | I8: Baghlan | J8: 5 | K8: 1 | L8: 6 | N8: Baghlan | O8: 1 | P8: 1 | Q8: 1 | S8: Baghlan | T8: AKF | U8: AKF | V8: 2 | W8: 3 | X8: 5 | Y8: 10 | Z8: 1 | AA8: 0 | AB8: 0 | AC8: 1 | AD8: 11 | AF8: Baghlan | AG8: 10 | AH8: 1 | AI8: 11 | AK8: Baghlan | AL8: 1 | AM8: 1 | AN8: 1
A9: Balkh | B9: BDN | C9: BDN | D9: 2 | E9: 6 | F9: 1 | G9: 9 | I9: Balkh | J9: 8 | K9: 1 | L9: 9 | N9: Balkh | O9: 1 | P9: 1 | Q9: 1 | S9: Balkh | T9: BDN | U9: BDN | V9: 2 | W9: 6 | X9: 7 | Y9: 15 | Z9: 1 | AA9: 0 | AB9: 0 | AC9: 1 | AD9: 16 | AF9: Balkh | AG9: 15 | AH9: 1 | AI9: 16 | AK9: Balkh | AL9: 1 | AM9: 1 | AN9: 1
A10: Bamyan | B10: AKF | C10: AKF | D10: 1 | E10: 3 | F10: 1 | G10: 5 | I10: Bamyan | J10: 4 | K10: 1 | L10: 5 | N10: Bamyan | O10: 1 | P10: 1 | Q10: 1 | S10: Bamyan | T10: AKF | U10: AKF | V10: 1 | W10: 3 | X10: 6 | Y10: 10 | Z10: 1 | AA10: 0 | AB10: 0 | AC10: 1 | AD10: 11 | AF10: Bamyan | AG10: 10 | AH10: 1 | AI10: 11 | AK10: Bamyan | AL10: 1 | AM10: 1 | AN10: 1
A11: Faryab | B11: SAF | C11: SAF | D11: 3 | E11: 3 | F11: 1 | G11: 7 | I11: Faryab | J11: 6 | K11: 1 | L11: 7 | N11: Faryab | O11: 1 | P11: 1 | Q11: 1 | S11: Faryab | T11: SAF | U11: SAF | V11: 3 | W11: 3 | X11: 4 | Y11: 10 | Z11: 1 | AA11: 0 | AB11: 0 | AC11: 1 | AD11: 11 | AF11: Faryab | AG11: 10 | AH11: 1 | AI11: 11 | AK11: Faryab | AL11: 1 | AM11: 1 | AN11: 1
A12: Ghazni | B12: JACK | C12: JACK | D12: 4 | E12: 5 | F12: 1 | G12: 10 | I12: Ghazni | J12: 9 | K12: 1 | L12: 10 | N12: Ghazni | O12: 1 | P12: 1 | Q12: 1 | S12: Ghazni | T12: JACK | U12: JACK | V12: 4 | W12: 5 | X12: 6 | Y12: 15 | Z12: 1 | AA12: 0 | AB12: 0 | AC12: 1 | AD12: 16 | AF12: Ghazni | AG12: 15 | AH12: 1 | AI12: 16 | AK12: Ghazni | AL12: 1 | AM12: 1 | AN12: 1
A13: Ghor | B13: BARAN | C13: BARAN | D13: 1 | E13: 3 | F13: 1 | G13: 5 | I13: Ghor | J13: 4 | K13: 1 | L13: 5 | N13: Ghor | O13: 1 | P13: 1 | Q13: 1 | S13: Ghor | T13: BARAN | U13: BARAN | V13: 1 | W13: 3 | X13: 6 | Y13: 10 | Z13: 1 | AA13: 0 | AB13: 0 | AC13: 1 | AD13: 11 | AF13: Ghor | AG13: 10 | AH13: 1 | AI13: 11 | AK13: Ghor | AL13: 1 | AM13: 1 | AN13: 1
A14: Helmand | B14: RI | C14: RI | D14: 2 | E14: 6 | F14: 1 | G14: 9 | I14: Helmand | J14: 8 | K14: 1 | L14: 9 | N14: Helmand | O14: 1 | P14: 1 | Q14: 1 | S14: Helmand | T14: RI | U14: RI | V14: 2 | W14: 6 | X14: 7 | Y14: 15 | Z14: 1 | AA14: 0 | AB14: 0 | AC14: 1 | AD14: 16 | AF14: Helmand | AG14: 15 | AH14: 1 | AI14: 16 | AK14: Helmand | AL14: 1 | AM14: 1 | AN14: 1
A15: Herat | B15: AADA | C15: AADA | D15: 4 | E15: 5 | F15: 1 | G15: 10 | I15: Herat | J15: 9 | K15: 1 | L15: 10 | N15: Herat | O15: 1 | P15: 1 | Q15: 1 | S15: Herat | T15: AADA | U15: AADA | V15: 4 | W15: 5 | X15: 6 | Y15: 15 | Z15: 1 | AA15: 0 | AB15: 0 | AC15: 1 | AD15: 16 | AF15: Herat | AG15: 15 | AH15: 1 | AI15: 16 | AK15: Herat | AL15: 1 | AM15: 1 | AN15: 1
A16: Jawzjan | B16: SAF | C16: SAF | D16: 1 | E16: 4 | F16: 1 | G16: 6 | I16: Jawzjan | J16: 5 | K16: 1 | L16: 6 | N16: Jawzjan | O16: 1 | P16: 1 | Q16: 1 | S16: Jawzjan | T16: SAF | U16: SAF | V16: 1 | W16: 4 | X16: 5 | Y16: 10 | Z16: 1 | AA16: 0 | AB16: 0 | AC16: 1 | AD16: 11 | AF16: Jawzjan | AG16: 10 | AH16: 1 | AI16: 11 | AK16: Jawzjan | AL16: 1 | AM16: 1 | AN16: 1
A17: Kabul | B17: AKF | C17: AKF | D17: 2 | E17: 6 | F17: 1 | G17: 9 | I17: Kabul | J17: 8 | K17: 1 | L17: 9 | N17: Kabul | O17: 1 | P17: 1 | Q17: 1 | S17: Kabul | T17: AKF | U17: AKF | V17: 2 | W17: 6 | X17: 2 | Y17: 10 | Z17: 1 | AA17: 0 | AB17: 0 | AC17: 1 | AD17: 11 | AF17: Kabul | AG17: 10 | AH17: 1 | AI17: 11 | AK17: Kabul | AL17: 1 | AM17: 1 | AN17: 1
A18: Kandahar | B18: JACK | C18: JACK | D18: 3 | E18: 4 | F18: 1 | G18: 8 | I18: Kandahar | J18: 7 | K18: 1 | L18: 8 | N18: Kandahar | O18: 1 | P18: 1 | Q18: 1 | S18: Kandahar | T18: JACK | U18: JACK | V18: 3 | W18: 4 | X18: 8 | Y18: 15 | Z18: 1 | AA18: 0 | AB18: 0 | AC18: 1 | AD18: 16 | AF18: Kandahar | AG18: 15 | AH18: 1 | AI18: 16 | AK18: Kandahar | AL18: 1 | AM18: 1 | AN18: 1
A19: Kunar | B19: HNTPO | C19: HNTPO | D19: 1 | E19: 3 | F19: 1 | G19: 5 | I19: Kunar | J19: 4 | K19: 1 | L19: 5 | N19: Kunar | O19: 1 | P19: 1 | Q19: 1 | S19: Kunar | T19: HNTPO | U19: HNTPO | V19: 1 | W19: 3 | X19: 6 | Y19: 10 | Z19: 1 | AA19: 0 | AB19: 0 | AC19: 1 | AD19: 11 | AF19: Kunar | AG19: 10 | AH19: 1 | AI19: 11 | AK19: Kunar | AL19: 1 | AM19: 1 | AN19: 1
... A21: Logar | B21: CAF | C21: CAF | D21: 2 | E21: 5 | F21: 1 | G21: 8 | I21: Logar | J21: 7 | K21: 1 | L21: 8 | N21: Logar | O21: 1 | P21: 1 | Q21: 1 | S21: Logar | T21: CAF | U21: CAF | V21: 2 | W21: 5 | X21: 3 | Y21: 10 | Z21: 1 | AA21: 0 | AB21: 0 | AC21: 1 | AD21: 11 | AF21: Logar | AG21: 10 | AH21: 1 | AI21: 11 | AK21: Logar | AL21: 1 | AM21: 1 | AN21: 1
A22: Nimroz | B22: RI-MRCA | C22: RI-MRCA | D22: 2 | E22: 4 | F22: 0 | G22: 6 | I22: Nimroz | J22: 6 | K22: 0 | L22: 6 | N22: Nimroz | O22: 1 | Q22: 1 | S22: Nimroz | T22: RI-MRCA | U22: RI-MRCA | V22: 2 | W22: 4 | X22: 4 | Y22: 10 | Z22: 0 | AA22: 1 | AB22: 0 | AC22: 1 | AD22: 11 | AF22: Nimroz | AG22: 10 | AH22: 1 | AI22: 11 | AK22: Nimroz | AL22: 1 | AM22: 1 | AN22: 1
A23: Nuristan | B23: AADA | C23: AADA | D23: 1 | E23: 2 | F23: 1 | G23: 4 | I23: Nuristan | J23: 3 | K23: 1 | L23: 4 | N23: Nuristan | O23: 1 | P23: 1 | Q23: 1 | S23: Nuristan | T23: AADA | U23: AADA | V23: 1 | W23: 2 | X23: 7 | Y23: 10 | Z23: 1 | AA23: 0 | AB23: 0 | AC23: 1 | AD23: 11 | AF23: Nuristan | AG23: 10 | AH23: 1 | AI23: 11 | AK23: Nuristan | AL23: 1 | AM23: 1 | AN23: 1
A24: Paktika | B24: BARAN | C24: BARAN | D24: 2 | E24: 3 | F24: 1 | G24: 6 | I24: Paktika | J24: 5 | K24: 1 | L24: 6 | N24: Paktika | O24: 1 | P24: 1 | Q24: 1 | S24: Paktika | T24: BARAN | U24: BARAN | V24: 2 | W24: 3 | X24: 5 | Y24: 10 | Z24: 1 | AA24: 0 | AB24: 0 | AC24: 1 | AD24: 11 | AF24: Paktika | AG24: 10 | AH24: 1 | AI24: 11 | AK24: Paktika | AL24: 1 | AM24: 1 | AN24: 1
A25: Paktya | B25: AADA | C25: AADA | D25: 2 | E25: 4 | F25: 1 | G25: 7 | I25: Paktya | J25: 6 | K25: 1 | L25: 7 | N25: Paktya | O25: 1 | P25: 1 | Q25: 1 | S25: Paktya | T25: AADA | U25: AADA | V25: 2 | W25: 4 | X25: 4 | Y25: 10 | Z25: 1 | AA25: 0 | AB25: 0 | AC25: 1 | AD25: 11 | AF25: Paktya | AG25: 10 | AH25: 1 | AI25: 11 | AK25: Paktya | AL25: 1 | AM25: 1 | AN25: 1
A26: Panjsher | B26: MOVE | C26: MOVE | D26: 1 | E26: 3 | F26: 1 | G26: 5 | I26: Panjsher | J26: 4 | K26: 1 | L26: 5 | N26: Panjsher | O26: 1 | P26: 1 | Q26: 1 | S26: Panjsher | T26: MOVE | U26: MOVE | V26: 1 | W26: 3 | X26: 6 | Y26: 10 | Z26: 1 | AA26: 0 | AB26: 0 | AC26: 1 | AD26: 11 | AF26: Panjsher | AG26: 10 | AH26: 1 | AI26: 11 | AK26: Panjsher | AL26: 1 | AM26: 1 | AN26: 1
A27: Parwan | B27: JACK | C27: JACK | D27: 1 | E27: 4 | F27: 0 | G27: 5 | I27: Parwan | J27: 5 | K27: 0 | L27: 5 | N27: Parwan | O27: 1 | Q27: 1 | S27: Parwan | T27: JACK | U27: JACK | V27: 1 | W27: 4 | X27: 5 | Y27: 10 | Z27: 0 | AA27: 1 | AB27: 0 | AC27: 1 | AD27: 11 | AF27: Parwan | AG27: 10 | AH27: 1 | AI27: 11 | AK27: Parwan | AL27: 1 | AM27: 1 | AN27: 1
A28: Samangan | B28: MMRCA | C28: MMRCA | D28: 1 | E28: 4 | F28: 1 | G28: 6 | I28: Samangan | J28: 5 | K28: 1 | L28: 6 | N28: Samangan | O28: 1 | P28: 1 | Q28: 1 | S28: Samangan | T28: MMRCA | U28: MMRCA | V28: 1 | W28: 4 | X28: 5 | Y28: 10 | Z28: 1 | AA28: 0 | AB28: 0 | AC28: 1 | AD28: 11 | AF28: Samangan | AG28: 10 | AH28: 1 | AI28: 11 | AK28: Samangan | AL28: 1 | AM28: 1 | AN28: 1
A29: Sar-e-Pul | B29: MMRCA | C29: MMRCA | D29: 1 | E29: 3 | F29: 1 | G29: 5 | I29: Sar-e-Pul | J29: 4 | K29: 1 | L29: 5 | N29: Sar-e-Pul | O29: 1 | P29: 1 | Q29: 1 | S29: Sar-e-Pul | T29: MMRCA | U29: MMRCA | V29: 1 | W29: 3 | X29: 6 | Y29: 10 | Z29: 1 | AA29: 0 | AB29: 0 | AC29: 1 | AD29: 11 | AF29: Sar-e-Pul | AG29: 10 | AH29: 1 | AI29: 11 | AK29: Sar-e-Pul | AL29: 1 | AM29: 1 | AN29: 1
A30: Takhar | B30: AKF | C30: AKF | D30: 2 | E30: 4 | F30: 1 | G30: 7 | I30: Takhar | J30: 6 | K30: 1 | L30: 7 | N30: Takhar | O30: 1 | P30: 1 | Q30: 1 | S30: Takhar | T30: AKF | U30: AKF | V30: 2 | W30: 4 | X30: 4 | Y30: 10 | Z30: 1 | AA30: 0 | AB30: 0 | AC30: 1 | AD30: 11 | AF30: Takhar | AG30: 10 | AH30: 1 | AI30: 11 | AK30: Takhar | AL30: 1 | AM30: 1 | AN30: 1
A31: Uruzgan | B31: AHDS | C31: AHDS | D31: 1 | E31: 3 | F31: 1 | G31: 5 | I31: Uruzgan | J31: 4 | K31: 1 | L31: 5 | N31: Uruzgan | O31: 1 | P31: 1 | Q31: 1 | S31: Uruzgan | T31: AHDS | U31: AHDS | V31: 1 | W31: 3 | X31: 6 | Y31: 10 | Z31: 1 | AA31: 0 | AB31: 0 | AC31: 1 | AD31: 11 | AF31: Uruzgan | AG31: 10 | AH31: 1 | AI31: 11 | AK31: Uruzgan | AL31: 1 | AM31: 1 | AN31: 1
A32: Wardak | B32: BDN | C32: BDN | D32: 1 | E32: 4 | F32: 1 | G32: 6 | I32: Wardak | J32: 5 | K32: 1 | L32: 6 | N32: Wardak | O32: 1 | P32: 1 | Q32: 1 | S32: Wardak | T32: BDN | U32: BDN | V32: 1 | W32: 4 | X32: 5 | Y32: 10 | Z32: 1 | AA32: 0 | AB32: 0 | AC32: 1 | AD32: 11 | AF32: Wardak | AG32: 10 | AH32: 1 | AI32: 11 | AK32: Wardak | AL32: 1 | AM32: 1 | AN32: 1

Sheet 2-QQM_SUMMARY_SHEET
A1: Province | B1: Service provider | C1: QQM - Structural indicators - HER2 R4 - October to December 2024 | O1: QQM - Outcome quality - HER2 R4 - October to December 2024 | S1: QQM - Content of care - HER2 R4 - October to December 2024 | U1: QQM Score
C2: Domain 1: General Management | D2: Domain 2: Hygiene | E2: Domain 3: OPD / Curative Consultations | F2: Domain 4: Family planning | G2: Domain 5: Laboratory | H2: Domain 6: Essential Drugs Management | I2: Domain 7: Tracer drugs | J2: Domain 8: Maternity | K2: Domain 9: EPI | L2: Domain 10: Antenatal Care | M2: Structural indicators score | O2: Exit interview with caregiver of a sick child under 5 | P2: Exit interview Family Planning | Q2: Outcome quality score
A3: province_name | B3: SP | C3: gm_score | D3: hy_score | E3: opd_score | F3: fp_score | G3: lab_score | H3: edm_score | I3: rx_score | J3: mat_score | K3: epi_score | L3: anc_score | M3: qqm_si_score | N3: blank1 | O3: u5_result | P3: fp_result | Q3: outcome_score | R3: blank2 | S3: content_score
A4: Badakhshan | B4: AKF | C4: 0.8571429 | D4: 0.6740196 | E4: 0.7329546 | F4: 0.5652174 | G4: 0.9777778 | H4: 0.5705128 | I4: 0.2037037 | J4: 0.729885 | K4: 0.9753087 | L4: 0.7820513 | M4: 0.5792104 | O4: 0.536875 | P4: 0.7075 | Q4: 0.6221875 | S4: 0.6348438 | U4: =(0.4*M4)+(0.2*Q4)+(0.4*S4) -> 0.61005918
A5: Baghlan | B5: AKF | C5: 0.797619 | D5: 0.5931373 | E5: 0.5246212 | F5: 0.5869565 | G5: 0.7888889 | H5: 0.6217949 | I5: 0.0296296 | J5: 0.7643678 | K5: 0.8518519 | L5: 0.5961539 | M5: 0.4916911 | O5: 0.5454546 | P5: 0.7354546 | Q5: 0.6404545 | S5: 0.6865909 | U5: =(0.4*M5)+(0.2*Q5)+(0.4*S5) -> 0.5994037
A6: Balkh | B6: BDN | C6: 0.7063492 | D6: 0.5522876 | E6: 0.6186869 | F6: 0.5652174 | G6: 0.8 | H6: 0.6025641 | I6: 0.1298765 | J6: 0.8045977 | K6: 0.9053498 | L6: 0.7777778 | M6: 0.5250756 | O6: 0.4675 | P6: 0.65 | Q6: 0.55875 | S6: 0.461875 | U6: =(0.4*M6)+(0.2*Q6)+(0.4*S6) -> 0.50653024
A7: Bamyan | B7: AKF | C7: 0.6 | D7: 0.5617647 | E7: 0.4954545 | F7: 0.7304348 | G7: 0.7833334 | H7: 0.7153846 | I7: 0.0388889 | J7: 0.8068966 | K7: 0.8814815 | L7: 0.8384615 | M7: 0.5156805 | O7: 0.4841667 | P7: 0.7166666 | Q7: 0.5838095 | S7: 0.5885227 | U7: =(0.4*M7)+(0.2*Q7)+(0.4*S7) -> 0.55844318
A8: Faryab | B8: SAF | C8: 0.6734694 | D8: 0.5336134 | E8: 0.5551948 | F8: 0.5714286 | G8: 0.7733333 | H8: 0.456044 | I8: 0 | J8: 0.5517241 | K8: 0.8941799 | L8: 0.521978 | M8: 0.4278744 | O8: 0.442 | P8: 0.6486363 | Q8: 0.5502381 | S8: 0.5242046 | U8: =(0.4*M8)+(0.2*Q8)+(0.4*S8) -> 0.49087922
A9: Ghazni | B9: JACK | C9: 0.6607143 | D9: 0.5 | E9: 0.7079545 | F9: 0.6478261 | G9: 0.7866667 | H9: 0.7384616 | I9: 0.0422222 | J9: 0.7724138 | K9: 0.7962963 | L9: 0.7961538 | M9: 0.5236881 | O9: 0.4047059 | P9: 0.754 | Q9: 0.5684375 | S9: 0.4406452 | U9: =(0.4*M9)+(0.2*Q9)+(0.4*S9) -> 0.49942082
A10: Ghor | B10: BARAN | C10: 0.6 | D10: 0.5794117 | E10: 0.5863636 | F10: 0.6 | G10: 0.8666667 | H10: 0.5307692 | I10: 0.2142222 | J10: 0.6551724 | K10: 0.8296296 | L10: 0.5076923 | M10: 0.5053614 | O10: 0.46 | P10: 0.6181818 | Q10: 0.5390909 | S10: 0.6223863 | U10: =(0.4*M10)+(0.2*Q10)+(0.4*S10) -> 0.55891726
A11: Helmand | B11: RI | C11: 0.4246032 | D11: 0.3464052 | E11: 0.3459596 | F11: 0.2801932 | G11: 0.6166667 | H11: 0.3418804 | I11: 0 | J11: 0.5440613 | K11: 0.8271605 | L11: 0.3846154 | M11: 0.3137943 | O11: 0.37 | P11: 0.6214285 | Q11: 0.48 | S11: 0.2405833 | U11: =(0.4*M11)+(0.2*Q11)+(0.4*S11) -> 0.31775104
A12: Herat | B12: AADA | C12: 0.7 | D12: 0.7205882 | E12: 0.6068182 | F12: 0.5826087 | G12: 0.8074074 | H12: 0.6038461 | I12: 0.0173333 | J12: 0.7827586 | K12: 0.9 | L12: 0.7884616 | M12: 0.5169661 | O12: 0.376875 | P12: 0.679375 | Q12: 0.528125 | S12: 0.459375 | U12: =(0.4*M12)+(0.2*Q12)+(0.4*S12) -> 0.49616144
A13: Jawzjan | B13: SAF | C13: 0.7321429 | D13: 0.8088235 | E13: 0.5416667 | F13: 0.4782609 | G13: 0.8 | H13: 0.4871795 | I13: 0 | J13: 0.7758621 | K13: 0.9320987 | L13: 0.7948718 | M13: 0.4831319 | O13: 0.5084615 | P13: 0.6733333 | Q13: 0.5759091 | S13: 0.5603572 | U13: =(0.4*M13)+(0.2*Q13)+(0.4*S13) -> 0.53257746
A14: Kabul | B14: AKF | C14: 0.8690476 | D14: 0.9101307 | E14: 0.5770202 | F14: 0.7004831 | G14: 0.9777778 | H14: 0.7222222 | I14: 0.2609877 | J14: 0.8467433 | K14: 0.9423868 | L14: 0.7222222 | M14: 0.6342397 | O14: 0.4209091 | P14: 0.5890909 | Q14: 0.505 | S14: 0.4647727 | U14: =(0.4*M14)+(0.2*Q14)+(0.4*S14) -> 0.54060496
A15: Kandahar | B15: JACK | C15: 0.625 | D15: 0.5183824 | E15: 0.484375 | F15: 0.4347826 | G15: 0.9833333 | H15: 0.5048077 | I15: 0.0472222 | J15: 0.737069 | K15: 0.8009259 | L15: 0.5192308 | M15: 0.4357196 | O15: 0.431875 | P15: 0.6325 | Q15: 0.5321875 | S15: 0.383125 | U15: =(0.4*M15)+(0.2*Q15)+(0.4*S15) -> 0.43397534
... A29: Wardak | B29: BDN | C29: 0.797619 | D29: 0.6200981 | E29: 0.5719697 | F29: 0.5797101 | G29: 0.6833333 | H29: 0.3717949 | I29: 0 | J29: 0.7873563 | K29: 0.8950617 | L29: 0.6217949 | M29: 0.452381 | O29: 0.4476923 | P29: 0.6722222 | Q29: 0.5395455 | S29: 0.5058333 | U29: =(0.4*M29)+(0.2*Q29)+(0.4*S29) -> 0.49119482
A30: National | C30: 0.7232175 | D30: 0.6238216 | E30: 0.6082178 | F30: 0.5656786 | G30: 0.810407 | H30: 0.6246443 | I30: 0.0897603 | J30: 0.7552513 | K30: 0.8842282 | L30: 0.6745228 | M30: 0.5176278 | O30: 0.4812733 | P30: 0.6849715 | Q30: 0.5775912 | S30: 0.4991356 | U30: =(0.4*M30)+(0.2*Q30)+(0.4*S30) -> 0.5222236
L31: P25 | M31: =_xlfn.PERCENTILE.INC(M4:M29,0.25) -> 0.46006872 | P31: P25 | Q31: =_xlfn.PERCENTILE.INC(Q4:Q29,0.25) -> 0.53687502 | R31: P25 | S31: =_xlfn.PERCENTILE.INC(S4:S29,0.25) -> 0.4242238 | T31: p25 | U31: =_xlfn.PERCENTILE.INC(U4:U29,0.25) -> 0.49095812
K32: =AVERAGE(C4:L4) -> 0.70685738 | L32: P50 | M32: =_xlfn.PERCENTILE.INC(M4:M29,0.5) -> 0.5203271 | P32: P50 | Q32: =_xlfn.PERCENTILE.INC(Q4:Q29,0.5) -> 0.5798593 | R32: P50 | S32: =_xlfn.PERCENTILE.INC(S4:S29,0.5) -> 0.50013255 | T32: p50 | U32: =_xlfn.PERCENTILE.INC(U4:U29,0.5) -> 0.52797822
I33: =AVERAGE(C4:L4) -> 0.70685738

Sheet 3-QQM_BY ROUND
A1: Province | B1: Service provider | C1: Structural Quality | U1: Outcome Quality | AM1: Content Quality
C2: HER Round 4 [95%CI] | E2: HER2 Round 1 [95%CI] | G2: HER2 Round 2 [95%CI] | I2: HER2 Round 3 [95%CI] | K2: HER2 Round 4 [95%CI] | M2: HER2 Round 5 [95%CI] | O2: Difference HER R4 and HER2 R1 | P2: Difference HER2 R1 and HER2 R2 | Q2: Difference HER2 R2 and HER2 R3 | R2: Difference HER2 R3 and HER2 R4 | S2: Difference HER2 R4 and HER2 R5 | U2: HER Round 4 [95%CI] | W2: HER2 Round 1 [95%CI] | Y2: HER2 Round 2 [95%CI] | AA2: HER2 Round 3 [95%CI] | AC2: HER2 Round 4 [95%CI] | AE2: HER2 Round 5 [95%CI] | AG2: Difference HER R4 and HER2 R1 | AH2: Difference HER2 R1 and HER2 R2 | AI2: Difference HER2 R2 and HER2 R3 | AJ2: Difference HER2 R3 and HER2 R4 | AK2: Difference HER2 R4 and HER2 R5 | AM2: HER Round 4 [95%CI] | AO2: HER2 Round 1 [95%CI] | AQ2: HER2 Round 2 [95%CI] | AS2: HER2 Round 3 [95%CI] | AU2: HER2 Round 4 [95%CI] | AW2: HER2 Round 5 [95%CI] | AY2: Difference HER R4 and HER2 R1 | AZ2: Difference HER2 R1 and HER2 R2 | BA2: Difference HER2 R2 and HER2 R3 | BB2: Difference HER2 R3 and HER2 R4 | BC2: Difference HER2 R4 and HER2 R5
I3: r3_six | J3: si_round3 | K3: r4_six | L3: si_round4 | Q3: r2_r3_si_changex | R3: r3_r4_si_changex | AA3: r3_ocx | AB3: oc_round3 | AC3: r4_ocx | AD3: oc_round4 | AI3: r2_r3_oc_changex | AJ3: r3_r4_oc_changex | AS3: r3_conx | AT3: con_round3 | AU3: r4_conx | AV3: con_round4 | BA3: r2_r3_con_changex | BB3: r3_r4_con_changex
A4: Badakhshan | B4: AKF | C4: 0.463 | D4: [41,3% - 53,7%] | E4: 0.441 | F4: [39.6% - 48%] | G4: 0.421 | H4: [36.6% - 46.8%] | I4: 0.523 | J4: [44.7% - 59.1%] | K4: 0.577 | L4: [50.6% - 65.5%] | O4: -0.022 | P4: -0.019 | Q4: 10.2%* | R4: 0.054 | U4: 0.668 | V4: [62,9% - 70,6%] | W4: 0.583 | X4: [52.7% - 64.3%] | Y4: 0.593 | Z4: [54.9% - 63.6%] | AA4: 0.584 | AB4: [52.2% - 66.1%] | AC4: 0.622 | AD4: [59.2% - 65.6%] | AG4: -0.085 | AH4: 0.011 | AI4: -0.01 | AJ4: 0.039 | AM4: 0.346 | AN4: [29,2% - 40%] | AO4: 0.335 | AP4: [27.5% - 40.2%] | AQ4: 0.327 | AR4: [25.5% - 39.4%] | AS4: 0.462 | AT4: [39.9% - 53.5%] | AU4: 0.635 | AV4: [56.5% - 70.7%] | AY4: -1,1%** | AZ4: -0.008 | BA4: 13.5%** | BB4: 17.3%***
A5: Badghis | B5: SAF | C5: 0.319 | D5: [24,2% - 39,8%] | E5: 0.499 | F5: [38.6% - 63.7%] | G5: 0.442 | H5: [37.1% - 52.3%] | I5: 0.381 | J5: [30.4% - 45.9%] | O5: 0.18 | P5: -0.057 | Q5: -0.06 | U5: 0.579 | V5: [53,4% - 62,6%] | W5: 0.537 | X5: [42.6% - 62.1%] | Y5: 0.467 | Z5: [39.3% - 54.3%] | AA5: 0.456 | AB5: [40.7% - 51.4%] | AG5: -0.042 | AH5: -0.07 | AI5: -0.011 | AM5: 0.262 | AN5: [21,2% - 31,1%] | AO5: 0.392 | AP5: [26.4% - 53.9%] | AQ5: 0.32 | AR5: [27.2% - 36.3%] | AS5: 0.466 | AT5: [42.1% - 51.2%] | AY5: 0.13 | AZ5: -0.072 | BA5: 14.6%***
A6: Baghlan | B6: AKF | C6: 0.355 | D6: [29,2% - 41,9%] | E6: 0.477 | F6: [41.2% - 53.6%] | G6: 0.552 | H6: [47.6% - 59.4%] | I6: 0.423 | J6: [38.5% - 46.2%] | K6: 0.492 | L6: [44.9% - 53.9%] | O6: 12,2%* | P6: 0.075 | Q6: -12.8%** | R6: 6.8%* | U6: 0.635 | V6: [59,8% - 66,9%] | W6: 0.628 | X6: [56.5% - 68.7%] | Y6: 0.553 | Z6: [49.8% - 60.7%] | AA6: 0.548 | AB6: [48.8% - 60.9%] | AC6: 0.64 | AD6: [57.5% - 70.2%] | AG6: -,7%** | AH6: -0.075 | AI6: -0.005 | AJ6: 9.2%* | AM6: 0.245 | AN6: [16,7% - 32,6%] | AO6: 0.532 | AP6: [45.8% - 60.4%] | AQ6: 0.606 | AR6: [53.8% - 67.1%] | AS6: 0.529 | AT6: [40.6% - 64.2%] | AU6: 0.687 | AV6: [56.4% - 79.1%] | AY6: 0.287 | AZ6: 0.073 | BA6: -0.077 | BB6: 0.158
A7: Balkh | B7: BDN | C7: 0.463 | D7: [42,3% - 50,4%] | E7: 0.616 | F7: [55.8% - 68%] | G7: 0.512 | H7: [43.2% - 59.9%] | I7: 0.555 | J7: [48.8% - 63.1%] | K7: 0.525 | L7: [47.3% - 57.1%] | O7: 15,4%*** | P7: -0.104 | Q7: 0.042 | R7: -0.03 | U7: 0.598 | V7: [55,5% - 64,3%] | W7: 0.568 | X7: [52.3% - 61.4%] | Y7: 0.572 | Z7: [49.9% - 64.6%] | AA7: 0.534 | AB7: [49.1% - 57.6%] | AC7: 0.559 | AD7: [51.6% - 59.6%] | AG7: -0.03 | AH7: 0.003 | AI7: -0.038 | AJ7: 0.025 | AM7: 0.471 | AN7: [40,9% - 52,4%] | AO7: 0.425 | AP7: [37.9% - 47.7%] | AQ7: 0.368 | AR7: [28.1% - 45.1%] | AS7: 0.584 | AT7: [54.1% - 62.1%] | AU7: 0.462 | AV7: [41.1% - 51.3%] | AY7: -4,6%*** | AZ7: -0.057 | BA7: 21.6%*** | BB7: -12.2%***
A8: Bamyan | B8: AKF | C8: 0.456 | D8: [36,5% - 55,6%] | E8: 0.509 | F8: [43.6% - 57.9%] | G8: 0.523 | H8: [42.7% - 62%] | I8: 0.563 | J8: [45.3% - 72%] | K8: 0.516 | L8: [45.6% - 56.1%] | O8: 0.053 | P8: 0.013 | Q8: 0.041 | R8: -0.047 | U8: 0.67 | V8: [64,1% - 70,1%] | W8: 0.627 | X8: [56.9% - 68.3%] | Y8: 0.587 | Z8: [52.5% - 63.8%] | AA8: 0.682 | AB8: [63.5% - 72.5%] | AC8: 0.584 | AD8: [53.9% - 64.2%] | AG8: -4,3%* | AH8: -0.04 | AI8: 9.4%* | AJ8: -9.8%** | AM8: 0.32 | AN8: [26,7% - 37,5%] | AO8: 0.531 | AP8: [45.8% - 59.2%] | AQ8: 0.41 | AR8: [36.4% - 45.5%] | AS8: 0.573 | AT8: [44.6% - 68.4%] | AU8: 0.589 | AV8: [47.9% - 68.3%] | AY8: 0.21 | AZ8: -12.1%** | BA8: 16.4%* | BB8: 0.015
A9: Daykundi | B9: MOVE | C9: 0.428 | D9: [32,9% - 51,3%] | E9: 0.412 | F9: [38.1% - 49.9%] | G9: 0.406 | H9: [37.2% - 44.3%] | I9: 0.489 | J9: [43.3% - 55.3%] | O9: -0.017 | P9: -0.041 | Q9: 8.3%* | U9: 0.617 | V9: [57,9% - 64,9%] | W9: 0.523 | X9: [49.3% - 55.1%] | Y9: 0.607 | Z9: [56.4% - 65.2%] | AA9: 0.669 | AB9: [60.5% - 74.7%] | AG9: -0.093 | AH9: 8.4%** | AI9: 0.062 | AM9: 0.354 | AN9: [28,4% - 44%] | AO9: 0.57 | AP9: [49.4% - 64.1%] | AQ9: 0.577 | AR9: [47.4% - 67.4%] | AS9: 0.6 | AT9: [52.8% - 67.9%] | AY9: 0.216 | AZ9: 0.007 | BA9: 0.023
A10: Farah | B10: JACK | C10: 0.365 | D10: [30,9% - 42,1%] | E10: 0.504 | F10: [47.5% - 52.5%] | G10: 0.373 | H10: [28.2% - 43.5%] | I10: 0.448 | J10: [36.5% - 53.1%] | O10: 0.139 | P10: -13%*** | Q10: 0.074 | U10: 0.704 | V10: [65,4% - 74,5%] | W10: 0.632 | X10: [60.4% - 65.9%] | Y10: 0.535 | Z10: [48.9% - 58.3%] | AA10: 0.588 | AB10: [52.9% - 65.2%] | AG10: -7,1%** | AH10: -9.7%*** | AI10: 0.053 | AM10: 0.193 | AN10: [14,7% - 24,3%] | AO10: 0.443 | AP10: [42.4% - 46.5%] | AQ10: 0.354 | AR10: [28.1% - 42.9%] | AS10: 0.394 | AT10: [31.4% - 47.7%] | AY10: 25,1%* | AZ10: -8.9%* | BA10: 0.04
A11: Faryab | B11: SAF | C11: 0.373 | D11: [33,4% - 40,6%] | E11: 0.356 | F11: [28.7% - 42.4%] | G11: 0.429 | H11: [37% - 47.7%] | I11: 0.42 | J11: [32.1% - 52.2%] | K11: 0.427 | L11: [36.9% - 48.5%] | O11: -0.018 | P11: 0.073 | Q11: -0.01 | R11: 0.008 | U11: 0.656 | V11: [60,6% - 70,8%] | W11: 0.523 | X11: [41.9% - 58.8%] | Y11: 0.598 | Z11: [56.4% - 63.4%] | AA11: 0.629 | AB11: [58.6% - 66.6%] | AC11: 0.55 | AD11: [50.3% - 63.1%] | AG11: -0.132 | AH11: 7.5%* | AI11: 0.031 | AJ11: -0.079 | AM11: 0.308 | AN11: [25,8% - 35,8%] | AO11: 0.418 | AP11: [33.3% - 47%] | AQ11: 0.35 | AR11: [29.1% - 40.6%] | AS11: 0.442 | AT11: [36.7% - 51.1%] | AU11: 0.524 | AV11: [42.9% - 61.3%] | AY11: 0.11 | AZ11: -0.068 | BA11: 0.092 | BB11: 0.082
A12: Ghazni | B12: JACK | C12: 0.38 | D12: [34,9% - 41,2%] | E12: 0.425 | F12: [38% - 47.9%] | G12: 0.335 | H12: [27.7% - 37.6%] | I12: 0.441 | J12: [37.3% - 50.4%] | K12: 0.523 | L12: [47% - 58.8%] | O12: 0.045 | P12: -9%* | Q12: 10.5%** | R12: 0.083 | U12: 0.646 | V12: [60% - 69%] | W12: 0.64 | X12: [61.7% - 66%] | Y12: 0.624 | Z12: [58.8% - 66%] | AA12: 0.572 | AB12: [54% - 60.5%] | AC12: 0.568 | AD12: [51.1% - 62.9%] | AG12: -0.006 | AH12: -0.015 | AI12: -5.2%* | AJ12: -0.004 | AM12: 0.28 | AN12: [24,3% - 32,2%] | AO12: 0.267 | AP12: [24.4% - 30.1%] | AQ12: 0.306 | AR12: [27% - 34.2%] | AS12: 0.322 | AT12: [27.6% - 35%] | AU12: 0.441 | AV12: [38.5% - 50.5%] | AY12: -0.013 | AZ12: 0.039 | BA12: 0.016 | BB12: 11.8%***
A13: Ghor | B13: BARAN | C13: 0.399 | D13: [36,8% - 43,1%] | E13: 0.483 | F13: [37.3% - 62.9%] | G13: 0.498 | H13: [46.2% - 53.3%] | I13: 0.452 | J13: [30% - 59.4%] | K13: 0.503 | L13: [39.9% - 66.8%] | O13: 8,4%* | P13: 0.015 | Q13: -0.046 | R13: 0.051 | U13: 0.585 | V13: [55,3% - 61,8%] | W13: 0.668 | X13: [59.9% - 73%] | Y13: 0.529 | Z13: [39.6% - 62.5%] | AA13: 0.75 | AB13: [70% - 81.7%] | AC13: 0.539 | AD13: [47.6% - 60.5%] | AG13: 0.083 | AH13: -13.9%* | AI13: 22%*** | AJ13: -21%*** | AM13: 0.446 | AN13: [39,3% - 49,9%] | AO13: 0.466 | AP13: [37.4% - 56.2%] | AQ13: 0.407 | AR13: [31.5% - 50.6%] | AS13: 0.605 | AT13: [51.6% - 69.1%] | AU13: 0.622 | AV13: [54.2% - 70.4%] | AY13: 0.02 | AZ13: -0.058 | BA13: 19.7%** | BB13: 0.018
A14: Helmand | B14: RI | C14: 0.272 | D14: [22% - 32,7%] | E14: 0.296 | F14: [23% - 36.7%] | G14: 0.33 | H14: [29.7% - 36.1%] | I14: 0.231 | J14: [19.2% - 26.9%] | K14: 0.314 | L14: [28.8% - 34.4%] | O14: 2,4%* | P14: 0.033 | Q14: -9.9%*** | R14: 8.3%** | U14: 0.532 | V14: [49,2% - 57,5%] | W14: 0.443 | X14: [36.5% - 51.3%] | Y14: 0.42 | Z14: [38.9% - 45.1%] | AA14: 0.464 | AB14: [42.8% - 50.5%] | AC14: 0.48 | AD14: [41.1% - 55.1%] | AG14: -0.089 | AH14: -0.024 | AI14: 0.045 | AJ14: 0.016 | AM14: 0.263 | AN14: [22,6% - 30,3%] | AO14: 0.308 | AP14: [25.4% - 38.2%] | AQ14: 0.233 | AR14: [18% - 28.3%] | AS14: 0.202 | AT14: [15.6% - 23.7%] | AU14: 0.241 | AV14: [19.4% - 29.6%] | AY14: 4,5%* | AZ14: -7.6%* | BA14: -0.031 | BB14: 0.039
A15: Herat | B15: AADA | C15: 0.417 | D15: [38,7% - 44,4%] | E15: 0.423 | F15: [38.5% - 45.5%] | G15: 0.459 | H15: [40.6% - 50.5%] | I15: 0.421 | J15: [37.6% - 46%] | K15: 0.517 | L15: [45.9% - 57.4%] | O15: 0.007 | P15: 0.036 | Q15: -0.038 | R15: 9.6%** | U15: 0.595 | V15: [55,1% - 64,3%] | W15: 0.558 | X15: [49.4% - 62.6%] | Y15: 0.617 | Z15: [55% - 68.1%] | AA15: 0.589 | AB15: [50.5% - 67.7%] | AC15: 0.528 | AD15: [45.2% - 59.9%] | AG15: -0.037 | AH15: 0.059 | AI15: -0.029 | AJ15: -0.061 | AM15: 0.373 | AN15: [31,7% - 43,3%] | AO15: 0.418 | AP15: [36.7% - 45.8%] | AQ15: 0.465 | AR15: [42.1% - 50.9%] | AS15: 0.402 | AT15: [35.6% - 44.3%] | AU15: 0.459 | AV15: [39.1% - 53.5%] | AY15: 4,5%* | AZ15: 0.047 | BA15: -6.3%* | BB15: 0.057
A16: Jawzjan | B16: SAF | C16: 0.582 | D16: [52,4% - 64,4%] | E16: 0.413 | F16: [37.2% - 45.1%] | G16: 0.435 | H16: [38.4% - 48.3%] | I16: 0.463 | J16: [41.3% - 53.1%] | K16: 0.483 | L16: [43.8% - 51.7%] | O16: -16,9%*** | P16: 0.022 | Q16: 0.028 | R16: 0.02 | U16: 0.669 | V16: [61,6% - 72,2%] | W16: 0.574 | X16: [53.9% - 65%] | Y16: 0.606 | Z16: [55.7% - 65.2%] | AA16: 0.528 | AB16: [47.8% - 57.6%] | AC16: 0.576 | AD16: [51.5% - 63.1%] | AG16: -0.094 | AH16: 0.032 | AI16: -7.8%* | AJ16: 0.048 | AM16: 0.489 | AN16: [38,3% - 60,6%] | AO16: 0.57 | AP16: [46.6% - 69.8%] | AQ16: 0.501 | AR16: [45.6% - 54.7%] | AS16: 0.564 | AT16: [50.2% - 61.4%] | AU16: 0.56 | AV16: [48.8% - 63.7%] | AY16: 8%*** | AZ16: -0.069 | BA16: 0.063 | BB16: -0.004
A17: Kabul | B17: AKF | C17: 0.504 | D17: [45,1% - 55,2%] | E17: 0.512 | F17: [46.9% - 55.3%] | G17: 0.574 | H17: [51.4% - 64.6%] | I17: 0.653 | J17: [60.1% - 70%] | K17: 0.634 | L17: [57.7% - 68.6%] | O17: 0.008 | P17: 0.062 | Q17: 0.079 | R17: -0.02 | U17: 0.64 | V17: [59,4% - 67,4%] | W17: 0.553 | X17: [50.4% - 60%] | Y17: 0.525 | Z17: [44.6% - 60.5%] | AA17: 0.541 | AB17: [49% - 59.7%] | AC17: 0.505 | AD17: [43.2% - 57.8%] | AG17: -0.086 | AH17: -0.029 | AI17: 0.017 | AJ17: -0.036 | AM17: 0.357 | AN17: [30,6% - 41,6%] | AO17: 0.516 | AP17: [44.1% - 58.9%] | AQ17: 0.479 | AR17: [34.2% - 62.3%] | AS17: 0.493 | AT17: [41.8% - 56.6%] | AU17: 0.465 | AV17: [38.8% - 55.2%] | AY17: 0.159 | AZ17: -0.037 | BA17: 0.013 | BB17: -0.028
A18: Kandahar | B18: JACK | C18: 0.298 | D18: [26% - 33,3%] | E18: 0.366 | F18: [33.5% - 39.3%] | G18: 0.432 | H18: [40.5% - 46.5%] | I18: 0.397 | J18: [34.3% - 44.8%] | K18: 0.434 | L18: [37.2% - 50.5%] | O18: 0.069 | P18: 6.5%** | Q18: -0.035 | R18: 0.038 | U18: 0.545 | V18: [48,6% - 59,6%] | W18: 0.505 | X18: [45.2% - 56%] | Y18: 0.586 | Z18: [54.5% - 62.2%] | AA18: 0.598 | AB18: [55.8% - 63.6%] | AC18: 0.532 | AD18: [48.5% - 58%] | AG18: -0.04 | AH18: 8.1%* | AI18: 0.012 | AJ18: -6.6%* | AM18: 0.263 | AN18: [21% - 32,2%] | AO18: 0.275 | AP18: [24.1% - 31.7%] | AQ18: 0.428 | AR18: [37.5% - 48.2%] | AS18: 0.45 | AT18: [38.9% - 52.4%] | AU18: 0.383 | AV18: [29.3% - 46.1%] | AY18: 1,2%* | AZ18: 15.2%*** | BA18: 0.023 | BB18: -0.067
A19: Kapisa | B19: BDN | C19: 0.394 | D19: [36,4% - 41,7%] | E19: 0.406 | F19: [35.9% - 45.1%] | G19: 0.396 | H19: [34.2% - 44.5%] | I19: 0.422 | J19: [37.9% - 46.3%] | O19: 1,2%** | P19: -0.01 | Q19: 0.027 | U19: 0.678 | V19: [61,8% - 72,7%] | W19: 0.485 | X19: [42.3% - 53.9%] | Y19: 0.496 | Z19: [43.7% - 55.5%] | AA19: 0.491 | AB19: [42.9% - 56.1%] | AG19: -0.194 | AH19: 0.012 | AI19: -0.005 | AM19: 0.431 | AN19: [38,9% - 46,7%] | AO19: 0.541 | AP19: [40.6% - 66.1%] | AQ19: 0.311 | AR19: [25.6% - 36.2%] | AS19: 0.383 | AT19: [31% - 45.6%] | AY19: 0.111 | AZ19: -23%*** | BA19: 0.071
A20: Khost | B20: HNTPO | C20: 0.368 | D20: [33% - 40,1%] | E20: 0.599 | F20: [57.2% - 63%] | G20: 0.634 | H20: [59.1% - 67.7%] | I20: 0.643 | J20: [60.1% - 68.2%] | O20: 0.231 | P20: 0.035 | Q20: 0.009 | U20: 0.586 | V20: [57,2% - 59,9%] | W20: 0.573 | X20: [49.6% - 64.7%] | Y20: 0.545 | Z20: [44.1% - 64.1%] | AA20: 0.669 | AB20: [59.1% - 74.2%] | AG20: -1,2%*** | AH20: -0.029 | AI20: 12.4%* | AM20: 0.219 | AN20: [17,6% - 25,7%] | AO20: 0.608 | AP20: [50.4% - 69.5%] | AQ20: 0.626 | AR20: [54.7% - 70.3%] | AS20: 0.616 | AT20: [52.9% - 69.3%] | AY20: 38,9%* | AZ20: 0.018 | BA20: -0.01
A21: Kunar | B21: HNTPO | C21: 0.512 | D21: [46,3% - 57,6%] | E21: 0.633 | F21: [59.2% - 68.7%] | G21: 0.615 | H21: [54.2% - 66.1%] | I21: 0.618 | J21: [57.9% - 65.2%] | K21: 0.605 | L21: [51.1% - 68.5%] | O21: 0.121 | P21: -0.018 | Q21: 0.003 | R21: -0.013 | U21: 0.525 | V21: [47,4% - 57,7%] | W21: 0.66 | X21: [57.8% - 73.6%] | Y21: 0.416 | Z21: [32.6% - 51.2%] | AA21: 0.633 | AB21: [57.6% - 68.9%] | AC21: 0.679 | AD21: [63.9% - 71.3%] | AG21: 13,5%*** | AH21: -24.4%*** | AI21: 21.7%*** | AJ21: 0.046 | AM21: 0.382 | AN21: [28,9% - 47,7%] | AO21: 0.657 | AP21: [52.1% - 79.5%] | AQ21: 0.7 | AR21: [62.4% - 77.7%] | AS21: 0.749 | AT21: [64.2% - 83.9%] | AU21: 0.725 | AV21: [65.6% - 79.8%] | AY21: 27,4%*** | AZ21: 0.043 | BA21: 0.05 | BB21: -0.025
A22: Kunduz | B22: JACK | C22: 0.332 | D22: [28,5% - 37,5%] | E22: 0.48 | F22: [44.4% - 51.5%] | G22: 0.492 | H22: [43.4% - 54.8%] | I22: 0.48 | J22: [42.2% - 54.4%] | K22: 0.593 | L22: [55.4% - 63.5%] | O22: 0.148 | P22: 0.012 | Q22: -0.012 | R22: 11.3%** | U22: 0.502 | V22: [46,1% - 54,8%] | W22: 0.497 | X22: [43.6% - 56.2%] | Y22: 0.5 | Z22: [45.4% - 54.9%] | AA22: 0.451 | AB22: [40.7% - 50%] | AC22: 0.586 | AD22: [52.5% - 63.6%] | AG22: -0.006 | AH22: 0.003 | AI22: -0.048 | AJ22: 13.5%*** | AM22: 0.237 | AN22: [20,8% - 26,6%] | AO22: 0.33 | AP22: [27.8% - 38.9%] | AQ22: 0.493 | AR22: [41.8% - 54.2%] | AS22: 0.478 | AT22: [44.2% - 51.6%] | AU22: 0.536 | AV22: [42.7% - 63.9%] | AY22: 0.093 | AZ22: 16.3%*** | BA22: -0.015 | BB22: 0.058
A23: Laghman | B23: HNTPO | C23: 0.647 | D23: [58,7% - 69,3%] | E23: 0.676 | F23: [56.3% - 77.7%] | G23: 0.722 | H23: [63.7% - 79.9%] | I23: 0.508 | J23: [45.8% - 56.6%] | O23: 2,9%*** | P23: 0.046 | Q23: -21.4%*** | U23: 0.542 | V23: [48% - 60,6%] | W23: 0.597 | X23: [45.8% - 72.1%] | Y23: 0.654 | Z23: [59% - 71.8%] | AA23: 0.518 | AB23: [45.1% - 59.8%] | AG23: 5,5%* | AH23: 0.056 | AI23: -13.6%** | AM23: 0.484 | AN23: [41,1% - 55,8%] | AO23: 0.671 | AP23: [58.9% - 75.7%] | AQ23: 0.636 | AR23: [53.7% - 72.2%] | AS23: 0.536 | AT23: [46.3% - 61%] | AY23: 18,7%*** | AZ23: -0.035 | BA23: -0.1
A24: Logar | B24: CAF | C24: 0.374 | D24: [34,1% - 40%] | E24: 0.574 | F24: [51.7% - 64%] | G24: 0.476 | H24: [42.6% - 52.4%] | I24: 0.638 | J24: [61.6% - 66.1%] | K24: 0.565 | L24: [51.2% - 60.8%] | O24: 20,1%*** | P24: -9.8%* | Q24: 16.2%*** | R24: -7.3%** | U24: 0.638 | V24: [57,9% - 69,2%] | W24: 0.615 | X24: [58.5% - 64.6%] | Y24: 0.519 | Z24: [47.7% - 55.9%] | AA24: 0.647 | AB24: [59.1% - 70%] | AC24: 0.657 | AD24: [56.8% - 73.3%] | AG24: -0.023 | AH24: -9.6%*** | AI24: 12.9%*** | AJ24: 0.01 | AM24: 0.473 | AN24: [38,7% - 54,2%] | AO24: 0.633 | AP24: [57.1% - 69.1%] | AQ24: 0.435 | AR24: [37.3% - 49%] | AS24: 0.573 | AT24: [49.6% - 65.8%] | AU24: 0.522 | AV24: [44.8% - 61%] | AY24: 16%*** | AZ24: -19.8%*** | BA24: 13.8%** | BB24: -0.051
A25: Nangarhar | B25: JACK | C25: 0.421 | D25: [36,8% - 47,2%] | E25: 0.49 | F25: [44.3% - 54.4%] | G25: 0.419 | H25: [37% - 46.3%] | I25: 0.398 | J25: [35.8% - 43.6%] | O25: 0.069 | P25: -0.071 | Q25: -0.021 | U25: 0.53 | V25: [49,7% - 57,4%] | W25: 0.554 | X25: [49.7% - 61.2%] | Y25: 0.591 | Z25: [53.5% - 64.6%] | AA25: 0.551 | AB25: [47.4% - 60.7%] | AG25: 0.024 | AH25: 0.037 | AI25: -0.04 | AM25: 0.275 | AN25: [22,4% - 33,5%] | AO25: 0.3 | AP25: [23.9% - 35.5%] | AQ25: 0.231 | AR25: [18.3% - 28.7%] | AS25: 0.35 | AT25: [26.3% - 41.2%] | AY25: 0.025 | AZ25: -0.069 | BA25: 11.8%*
A26: Nimroz | B26: RI-MRCA | C26: 0.378 | D26: [30,4% - 44,6%] | E26: 0.607 | F26: [49.3% - 71.3%] | G26: 0.683 | H26: [58.6% - 76.9%] | I26: 0.766 | J26: [70.5% - 83.3%] | K26: 0.66 | L26: [59.8% - 71.3%] | O26: 0.229 | P26: 0.076 | Q26: 0.083 | R26: -10.6%* | U26: 0.578 | V26: [53,7% - 61,9%] | W26: 0.608 | X26: [54% - 67.1%] | Y26: 0.639 | Z26: [58.2% - 69.8%] | AA26: 0.517 | AB26: [40.8% - 59%] | AC26: 0.592 | AD26: [54.9% - 63.8%] | AG26: 0.029 | AH26: 0.032 | AI26: -12.3%* | AJ26: 0.076 | AM26: 0.226 | AN26: [18,3% - 27,3%] | AO26: 0.566 | AP26: [42.3% - 71.5%] | AQ26: 0.559 | AR26: [36.6% - 75.7%] | AS26: 0.605 | AT26: [48.9% - 70.9%] | AU26: 0.621 | AV26: [55.3% - 68.6%] | AY26: 0.34 | AZ26: -0.007 | BA26: 0.045 | BB26: 0.017
A27: Nuristan | B27: AADA | C27: 0.543 | D27: [51% - 57,1%] | E27: 0.283 | F27: [25% - 30.8%] | G27: 0.451 | H27: [37.2% - 56.6%] | I27: 0.744 | J27: [59.3% - 89.5%] | K27: 0.639 | L27: [45.8% - 81.9%] | O27: -26%*** | P27: 16.8%** | Q27: 29.3%** | R27: -0.105 | U27: 0.659 | V27: [59,9% - 71,6%] | W27: 0.328 | X27: [28.5% - 37.8%] | Y27: 0.58 | Z27: [49.8% - 66.1%] | AA27: 0.632 | AB27: [53.5% - 73%] | AC27: 0.623 | AD27: [58.1% - 66.7%] | AG27: -0.331 | AH27: 25.2%*** | AI27: 0.052 | AJ27: -0.009 | AM27: 0.306 | AN27: [23,4% - 37,7%] | AO27: 0.239 | AP27: [18.5% - 28.8%] | AQ27: 0.399 | AR27: [31.8% - 49.3%] | AS27: 0.469 | AT27: [39.5% - 54.2%] | AU27: 0.542 | AV27: [48.5% - 60.1%] | AY27: -6,8%* | AZ27: 16%** | BA27: 0.07 | BB27: 0.074
A28: Paktika | B28: BARAN | C28: 0.381 | D28: [31,2% - 44,1%] | E28: 0.48 | F28: [41.9% - 54%] | G28: 0.514 | H28: [45.5% - 56.9%] | I28: 0.359 | J28: [30.4% - 42.1%] | K28: 0.392 | L28: [32.2% - 47%] | O28: 0.099 | P28: 0.033 | Q28: -15.5%*** | R28: 0.033 | U28: 0.723 | V28: [69,1% - 76%] | W28: 0.616 | X28: [56% - 66.5%] | Y28: 0.617 | Z28: [59.4% - 63.8%] | AA28: 0.433 | AB28: [36.3% - 49.8%] | AC28: 0.464 | AD28: [39% - 54.3%] | AG28: -10,7%*** | AH28: 0.001 | AI28: -18.4%*** | AJ28: 0.031 | AM28: 0.251 | AN28: [19,4% - 30%] | AO28: 0.371 | AP28: [30.9% - 43.5%] | AQ28: 0.371 | AR28: [32.1% - 42.3%] | AS28: 0.398 | AT28: [33.2% - 46.6%] | AU28: 0.343 | AV28: [27.8% - 40.4%] | AY28: 0.119 | AZ28: 0 | BA28: 0.027 | BB28: -0.055
A29: Paktya | B29: AADA | C29: 0.357 | D29: [29,6% - 44,8%] | E29: 0.353 | F29: [32.2% - 37.7%] | G29: 0.347 | H29: [30.1% - 39.3%] | I29: 0.385 | J29: [36.8% - 39.9%] | K29: 0.393 | L29: [37.1% - 41.6%] | O29: -0.004 | P29: -0.006 | Q29: 0.038 | R29: 0.008 | U29: 0.69 | V29: [66,6% - 71,8%] | W29: 0.53 | X29: [49% - 56.4%] | Y29: 0.541 | Z29: [48% - 61.3%] | AA29: 0.592 | AB29: [53% - 63.9%] | AC29: 0.508 | AD29: [42.4% - 58.9%] | AG29: -16,1%* | AH29: 0.012 | AI29: 0.051 | AJ29: -0.084 | AM29: 0.256 | AN29: [19% - 33,6%] | AO29: 0.403 | AP29: [32.8% - 48.1%] | AQ29: 0.484 | AR29: [43.9% - 53.3%] | AS29: 0.514 | AT29: [47.1% - 55.7%] | AU29: 0.419 | AV29: [32.4% - 48.8%] | AY29: 0.147 | AZ29: 0.081 | BA29: 0.03 | BB29: -9.5%*
A30: Panjsher | B30: MOVE | C30: 0.366 | D30: [34% - 38,7%] | E30: 0.388 | F30: [36.8% - 41.9%] | G30: 0.301 | H30: [28.3% - 31.7%] | I30: 0.418 | J30: [38.4% - 44.4%] | K30: 0.489 | L30: [46.7% - 51.5%] | O30: 0.022 | P30: -8.7%*** | Q30: 11.6%*** | R30: 7.2%*** | U30: 0.686 | V30: [66,4% - 71%] | W30: 0.623 | X30: [57.9% - 65.5%] | Y30: 0.564 | Z30: [52.4% - 61.1%] | AA30: 0.562 | AB30: [50.3% - 62.1%] | AC30: 0.594 | AD30: [53.5% - 64.2%] | AG30: -0.063 | AH30: -0.058 | AI30: -0.003 | AJ30: 0.033 | AM30: 0.286 | AN30: [26,8% - 30,6%] | AO30: 0.384 | AP30: [34.3% - 42.1%] | AQ30: 0.326 | AR30: [27% - 37.9%] | AS30: 0.38 | AT30: [30.8% - 44.4%] | AU30: 0.494 | AV30: [42.7% - 56.9%] | AY30: 9,8%*** | AZ30: -0.058 | BA30: 0.053 | BB30: 11.5%*
A31: Parwan | B31: JACK | C31: 0.315 | D31: [25,4% - 38%] | E31: 0.275 | F31: [23.3% - 32%] | G31: 0.445 | H31: [41% - 48%] | I31: 0.398 | J31: [34.9% - 45.7%] | K31: 0.411 | L31: [35.9% - 45.7%] | O31: -4%* | P31: 17.1%*** | Q31: -0.047 | R31: 0.012 | U31: 0.582 | V31: [52,3% - 63,3%] | W31: 0.528 | X31: [47.1% - 58.3%] | Y31: 0.529 | Z31: [46.5% - 59.8%] | AA31: 0.59 | AB31: [54% - 64.5%] | AC31: 0.536 | AD31: [47.2% - 58.4%] | AG31: -0.054 | AH31: 0.001 | AI31: 0.061 | AJ31: -0.054 | AM31: 0.217 | AN31: [17,3% - 27,3%] | AO31: 0.257 | AP31: [20.2% - 31.6%] | AQ31: 0.511 | AR31: [44.1% - 57.7%] | AS31: 0.338 | AT31: [27.9% - 40.2%] | AU31: 0.332 | AV31: [22.5% - 41.5%] | AY31: 0.04 | AZ31: 25.4%*** | BA31: -17.3%*** | BB31: -0.006
A32: Samangan | B32: MMRCA | C32: 0.557 | D32: [51,8% - 59,8%] | E32: 0.48 | F32: [44.7% - 51.2%] | G32: 0.562 | H32: [52.1% - 60.1%] | I32: 0.573 | J32: [52.1% - 62%] | K32: 0.587 | L32: [53% - 65%] | O32: -7,6%*** | P32: 8.2%** | Q32: 0.011 | R32: 0.014 | U32: 0.64 | V32: [59,8% - 69,2%] | W32: 0.589 | X32: [54.1% - 65.1%] | Y32: 0.552 | Z32: [51% - 59.3%] | AA32: 0.54 | AB32: [50.6% - 57.4%] | AC32: 0.609 | AD32: [54.8% - 66.9%] | AG32: -0.051 | AH32: -0.037 | AI32: -0.012 | AJ32: 6.9%* | AM32: 0.329 | AN32: [26,4% - 42%] | AO32: 0.371 | AP32: [30% - 45.2%] | AQ32: 0.381 | AR32: [34% - 42.3%] | AS32: 0.522 | AT32: [45.9% - 58%] | AU32: 0.481 | AV32: [41.5% - 54.8%] | AY32: 0.042 | AZ32: 0.01 | BA32: 14.2%*** | BB32: -0.042
A33: Sar-e-Pul | B33: MMRCA | C33: 0.348 | D33: [31,4% - 38,6%] | E33: 0.434 | F33: [35.1% - 53.3%] | G33: 0.444 | H33: [36.9% - 51.8%] | I33: 0.424 | J33: [37.7% - 46.9%] | K33: 0.546 | L33: [52.1% - 58.1%] | O33: 0.087 | P33: 0.009 | Q33: -0.019 | R33: 12.2%*** | U33: 0.579 | V33: [53,1% - 62,7%] | W33: 0.535 | X33: [46.6% - 61.5%] | Y33: 0.566 | Z33: [53% - 62.4%] | AA33: 0.504 | AB33: [45.5% - 55.4%] | AC33: 0.602 | AD33: [55.7% - 64.8%] | AG33: -0.044 | AH33: 0.031 | AI33: -6.2%* | AJ33: 9.8%** | AM33: 0.174 | AN33: [12,9% - 22,6%] | AO33: 0.37 | AP33: [28% - 45%] | AQ33: 0.345 | AR33: [28% - 40.5%] | AS33: 0.257 | AT33: [20.5% - 30.5%] | AU33: 0.339 | AV33: [25.5% - 42.8%] | AY33: 0.196 | AZ33: -0.025 | BA33: -8.7%* | BB33: 0.082
A34: Takhar | B34: AKF | C34: 0.375 | D34: [33,1% - 41,6%] | E34: 0.528 | F34: [48.3% - 57.7%] | G34: 0.522 | H34: [45.8% - 59.9%] | I34: 0.587 | J34: [50.6% - 67.4%] | K34: 0.582 | L34: [51.6% - 65.7%] | O34: 15,3%** | P34: -0.007 | Q34: 0.065 | R34: -0.005 | U34: 0.479 | V34: [42,8% - 55%] | W34: 0.55 | X34: [46.8% - 64%] | Y34: 0.579 | Z34: [53.3% - 62.2%] | AA34: 0.588 | AB34: [53% - 65.5%] | AC34: 0.648 | AD34: [61.7% - 68.3%] | AG34: 0.071 | AH34: 0.029 | AI34: 0.009 | AJ34: 0.06 | AM34: 0.317 | AN34: [27,3% - 37,1%] | AO34: 0.566 | AP34: [46% - 65.7%] | AQ34: 0.585 | AR34: [50.7% - 68.6%] | AS34: 0.663 | AT34: [59.9% - 71.7%] | AU34: 0.673 | AV34: [57.3% - 76.9%] | AY34: 25%* | AZ34: 0.019 | BA34: 0.077 | BB34: 0.01
A35: Uruzgan | B35: AHDS | C35: 0.303 | D35: [26,6% - 33,2%] | E35: 0.392 | F35: [36% - 42.7%] | G35: 0.321 | H35: [22.1% - 42.1%] | I35: 0.617 | J35: [52% - 69.6%] | K35: 0.584 | L35: [51.4% - 63.9%] | O35: 8,9%* | P35: -0.071 | Q35: 29.6%*** | R35: -0.033 | U35: 0.552 | V35: [51,7% - 58,3%] | W35: 0.508 | X35: [42% - 59%] | Y35: 0.514 | Z35: [41.7% - 61.8%] | AA35: 0.673 | AB35: [61.6% - 72.2%] | AC35: 0.696 | AD35: [65.3% - 73.8%] | AG35: -0.043 | AH35: 0.005 | AI35: 15.9%** | AJ35: 0.023 | AM35: 0.335 | AN35: [25,8% - 41,2%] | AO35: 0.458 | AP35: [37.1% - 54.2%] | AQ35: 0.325 | AR35: [23.5% - 43.6%] | AS35: 0.584 | AT35: [46.1% - 69%] | AU35: 0.377 | AV35: [32.4% - 43.1%] | AY35: 0.123 | AZ35: -0.133 | BA35: 25.9%** | BB35: -20.8%**
A36: Wardak | B36: BDN | C36: 0.435 | D36: [38,2% - 48,5%] | E36: 0.423 | F36: [32.4% - 52.6%] | G36: 0.395 | H36: [37.4% - 41.2%] | I36: 0.536 | J36: [50.1% - 57.6%] | K36: 0.452 | L36: [38.7% - 50.8%] | O36: -0.012 | P36: -0.028 | Q36: 14.1%*** | R36: -8.4%* | U36: 0.67 | V36: [62,8% - 71,4%] | W36: 0.474 | X36: [38.6% - 53.2%] | Y36: 0.497 | Z36: [47% - 52.8%] | AA36: 0.396 | AB36: [31% - 46.9%] | AC36: 0.54 | AD36: [46.6% - 61.6%] | AG36: -0.196 | AH36: 0.023 | AI36: -10.2%* | AJ36: 14.4%* | AM36: 0.39 | AN36: [31,5% - 47%] | AO36: 0.524 | AP36: [43.9% - 59.5%] | AQ36: 0.495 | AR36: [41.3% - 57.6%] | AS36: 0.52 | AT36: [40.1% - 63.8%] | AU36: 0.506 | AV36: [44% - 60.5%] | AY36: 0.135 | AZ36: -0.03 | BA36: 0.025 | BB36: -0.014
A37: Zabul | B37: MOVE | C37: 0.182 | D37: [14,7% - 21,7%] | E37: 0.485 | F37: [39.3% - 54.6%] | G37: 0.536 | H37: [51.1% - 56.3%] | I37: 0.32 | J37: [27.6% - 37.1%] | O37: 30,3%*** | P37: 0.05 | Q37: -21.6%*** | U37: 0.414 | V37: [32,3% - 49%] | W37: 0.593 | X37: [49.8% - 68.2%] | Y37: 0.75 | Z37: [70.1% - 79.5%] | AA37: 0.454 | AB37: [42% - 48.8%] | AG37: 0.18 | AH37: 15.7%** | AI37: -29.6%*** | AM37: 0.107 | AN37: [8,3% - 12,8%] | AO37: 0.504 | AP37: [29.9% - 62.9%] | AQ37: 0.719 | AR37: [65% - 77.4%] | AS37: 0.263 | AT37: [21.9% - 30.7%] | AY37: 39,6%** | AZ37: 21.5%** | BA37: -45.6%***
A38: National | C38: 0.402 | D38: [38.3% - 41.3%] | E38: 0.464 | F38: [44.7% - 48%] | G38: 0.471 | H38: [45.4% - 48.7%] | I38: 0.492 | J38: [46.4% - 50.2%] | K38: 0.518 | L38: [49.5% - 53.2%] | O38: 6.2%*** | P38: 0.007 | Q38: 0.021 | R38: 0.026 | U38: 0.606 | V38: [59.1% - 61.1%] | W38: 0.56 | X38: [54.6% - 57.1%] | Y38: 0.561 | Z38: [54.9% - 57.4%] | AA38: 0.564 | AB38: [55.2% - 57.6%] | AC38: 0.578 | AD38: [56.3% - 58.8%] | AG38: -4.6%*** | AH38: 0.001 | AI38: 0.003 | AJ38: 0.014 | AM38: 0.314 | AN38: [30.2% - 32.8%] | AO38: 0.448 | AP38: [41.9% - 45.3%] | AQ38: 0.443 | AR38: [41.6% - 45.1%] | AS38: 0.479 | AT38: [45.3% - 48.8%] | AU38: 0.499 | AV38: [47.3% - 51.4%] | AY38: 13.4%*** | AZ38: -0.005 | BA38: 3.6%** | BB38: 0.02
A39: No star = not significant
A40: * = p-value <0.05
...

Sheet Annex 1a - Structural_PROV
A1: HER2 R4 QQM - Structural Indicators October to December 2024 | C1: National | G1: Badakhshan | H1: Baghlan | I1: Balkh | J1: Bamyan | K1: Faryab | L1: Ghazni | M1: Ghor | N1: Helmand | O1: Herat | P1: Jawzjan | Q1: Kabul | R1: Kandahar | S1: Kunar | T1: Kunduz | U1: Logar | V1: Nimroz | W1: Nuristan | X1: Paktika | Y1: Paktya | Z1: Panjsher | AA1: Parwan | AB1: Samangan | AC1: Sar_e_Pul | AD1: Takhar | AE1: Uruzgan | AF1: Wardak
A2: Service provider | C2: Mean | D2: Median | E2: Min | F2: Max | G2: AKF | H2: AKF | I2: BDN | J2: AKF | K2: SAF | L2: JACK | M2: BARAN | N2: RI | O2: AADA | P2: SAF | Q2: AKF | R2: JACK | S2: HNTPO | T2: JACK | U2: CAF | V2: RI-MRCA | W2: AADA | X2: BARAN | Y2: AADA | Z2: MOVE | AA2: JACK | AB2: MMRCA | AC2: MMRCA | AD2: AKF | AE2: AHDS | AF2: BDN
A3: Sample information
A4: Number of BHC | G4: 4 | H4: 3 | I4: 6 | J4: 3 | K4: 3 | L4: 5 | M4: 3 | N4: 6 | O4: 5 | P4: 4 | Q4: 6 | R4: 4 | S4: 3 | T4: 4 | U4: 5 | V4: 4 | W4: 2 | X4: 3 | Y4: 4 | Z4: 3 | AA4: 4 | AB4: 4 | AC4: 3 | AD4: 4 | AE4: 3 | AF4: 4
A5: Number of CHC | G5: 2 | H5: 2 | I5: 2 | J5: 1 | K5: 3 | L5: 4 | M5: 1 | N5: 2 | O5: 4 | P5: 1 | Q5: 2 | R5: 3 | S5: 1 | T5: 2 | U5: 2 | V5: 2 | W5: 1 | X5: 2 | Y5: 2 | Z5: 1 | AA5: 1 | AB5: 1 | AC5: 1 | AD5: 2 | AE5: 1 | AF5: 1
A6: Number of DH | G6: 0 | H6: 1 | I6: 1 | J6: 1 | K6: 1 | L6: 1 | M6: 1 | N6: 1 | O6: 1 | P6: 1 | Q6: 1 | R6: 1 | S6: 1 | T6: 1 | U6: 1 | V6: 0 | W6: 1 | X6: 1 | Y6: 1 | Z6: 1 | AA6: 0 | AB6: 1 | AC6: 1 | AD6: 1 | AE6: 1 | AF6: 1
C7: N_mean | D7: N_median | E7: N_min | F7: N_max | G7: Badakhshan | H7: Baghlan | I7: Balkh | J7: Bamyan | K7: Faryab | L7: Ghazni | M7: Ghor | N7: Helmand | O7: Herat | P7: Jawzjan | Q7: Kabul | R7: Kandahar | S7: Kunar | T7: Kunduz | U7: Logar | V7: Nimroz | W7: Nuristan | X7: Paktika | Y7: Paktya | Z7: Panjsher | AA7: Parwan | AB7: Samangan | AC7: Sar_e_Pul | AD7: Takhar | AE7: Uruzgan | AF7: Wardak
A8: Domain 1: General Management | C8: 0.7232175 | D8: 0.7544643 | E8: 0.3511905 | F8: 0.8714285 | G8: 0.85714287 | H8: 0.79761904 | I8: 0.70634919 | J8: 0.60000002 | K8: 0.67346936 | L8: 0.66071427 | M8: 0.60000002 | N8: 0.42460316 | O8: 0.69999999 | P8: 0.73214287 | Q8: 0.86904764 | R8: 0.625 | S8: 0.85714287 | T8: 0.68367344 | U8: 0.7589286 | V8: 0.77976191 | W8: 0.85714287 | X8: 0.35119048 | Y8: 0.61734694 | Z8: 0.87142855 | AA8: 0.75 | AB8: 0.79761904 | AC8: 0.77857143 | AD8: 0.8214286 | AE8: 0.83571428 | AF8: 0.79761904
A9: 1 | B9: Presence of map of health facility catchment area | C9: 0.5767857 | D9: 0.6 | E9: 0 | F9: 1 | G9: 0.83333331 | H9: 0.33333334 | I9: 0.55555558 | J9: 0.80000001 | K9: 0.2857143 | L9: 0.60000002 | M9: 0.2 | N9: 0 | O9: 0.2 | P9: 1 | Q9: 0.77777779 | R9: 0.125 | S9: 1 | T9: 0.85714287 | U9: 0.5 | V9: 0.5 | W9: 0.5 | X9: 0 | Y9: 1 | Z9: 0.80000001 | AA9: 0.60000002 | AB9: 0.66666669 | AC9: 0.80000001 | AD9: 0.42857143 | AE9: 0.80000001 | AF9: 0.83333331
A10: 2 | B10: Proper filing system | C10: 0.8489103 | D10: 0.86 | E10: 0.5555556 | F10: 1 | G10: 0.83333331 | H10: 0.93333334 | I10: 0.55555558 | J10: 0.95999998 | K10: 0.91428572 | L10: 0.69999999 | M10: 0.83999997 | N10: 0.60000002 | O10: 0.75999999 | P10: 0.76666665 | Q10: 0.97777778 | R10: 0.82499999 | S10: 0.92000002 | T10: 0.97142857 | U10: 1 | V10: 1 | W10: 1 | X10: 0.63333333 | Y10: 0.80000001 | Z10: 0.88 | AA10: 0.88 | AB10: 0.80000001 | AC10: 1 | AD10: 0.91428572 | AE10: 0.83999997 | AF10: 0.76666665
A11: 3 | B11: Staff duty roster | C11: 0.845116 | D11: 0.95 | E11: 0.3333333 | F11: 1 | G11: 0.83333331 | H11: 0.83333331 | I11: 1 | J11: 0.80000001 | K11: 1 | L11: 0.89999998 | M11: 0.80000001 | N11: 0.44444445 | O11: 0.69999999 | P11: 0.66666669 | Q11: 1 | R11: 1 | S11: 1 | T11: 0.85714287 | U11: 1 | V11: 1 | W11: 1 | X11: 0.33333334 | Y11: 0.5714286 | Z11: 1 | AA11: 1 | AB11: 1 | AC11: 0.40000001 | AD11: 1 | AE11: 1 | AF11: 0.83333331
A12: 4 | B12: Technical meetings | C12: 0.6113706 | D12: 0.6614583 | E12: 0.1666667 | F12: 0.9166667 | G12: 0.91666669 | H12: 0.66666669 | I12: 0.69444442 | J12: 0.2 | K12: 0.32142857 | L12: 0.57499999 | M12: 0.40000001 | N12: 0.41666666 | O12: 0.69999999 | P12: 0.54166669 | Q12: 0.83333331 | R12: 0.53125 | S12: 0.64999998 | T12: 0.42857143 | U12: 0.65625 | V12: 0.625 | W12: 0.6875 | X12: 0.16666667 | Y12: 0.39285713 | Z12: 0.75 | AA12: 0.80000001 | AB12: 0.83333331 | AC12: 0.80000001 | AD12: 0.75 | AE12: 0.85000002 | AF12: 0.70833331
A13: 5 | B13: Standard referral sheets | C13: 0.9837607 | D13: 1 | E13: 0.7777778 | F13: 1 | G13: 1 | H13: 1 | I13: 1 | J13: 1 | K13: 1 | L13: 0.89999998 | M13: 1 | N13: 0.77777779 | O13: 0.89999998 | P13: 1 | Q13: 1 | R13: 1 | S13: 1 | T13: 1 | U13: 1 | V13: 1 | W13: 1 | X13: 1 | Y13: 1 | Z13: 1 | AA13: 1 | AB13: 1 | AC13: 1 | AD13: 1 | AE13: 1 | AF13: 1
A14: 6 | B14: Availability of dedicated mobile phone for communication between health facility and general hospital | C14: 0.2588217 | D14: 0.1833333 | E14: 0 | F14: 0.8888889 | G14: 0.33333334 | H14: 0.33333334 | I14: 0.33333334 | J14: 0.40000001 | K14: 0 | L14: 0 | M14: 0 | N14: 0 | O14: 0.2 | P14: 0 | Q14: 0.8888889 | R14: 0 | S14: 0.80000001 | T14: 0.14285715 | U14: 0.25 | V14: 0.66666669 | W14: 0.5 | X14: 0 | Y14: 0 | Z14: 0.60000002 | AA14: 0 | AB14: 0 | AC14: 0 | AD14: 0.71428573 | AE14: 0.40000001 | AF14: 0.16666667
