Workbook

Sheet Overview
A2: Worksheet | B2: Content
A3: Indicator list-QQC structural | B3: Definition and descripton of indicators
A4: 1-QQM_SUMMARY_SHEET | B4: Summary overview of the QQM indicators, per domain and province
A5: 2-QQM_BY ROUND | B5: Provincial QQM structural, outcome and content quality scores, per round and province
A6: Annex 1a - QQC_Structural_PROV | B6: Detailed overview of the scores for QQC structural quality, per province
A7: Annex1b-QQC_Structural_FAC | B7: Detailed overview of the scores for QQC structural quality, per health facility
A8: Annex1c-QQC_Tracerdrugs_PROV | B8: Detailed overview of availability of tracer drugs, per province
A9: Annex2a-QQM_EXIT&VIGNETTES_PROV | B9: Detailed overview of the scores for QQM outcome quality (exit interviews) and content of care(vignettes) indicators, per province
A10: Annex 2b-QQC_EXIT&VIGNETTES_FAC | B10: Detailed overview of the scores for QQM outcome quality (exit interviews) and content of care(vignettes) indicators, per health facility
A11: Annex 3a-HEALTH WORKERS - PROV | B11: Detailed overview of the scores for non-QQM indicators on Staffing (Salary payment, Health staff availability, GBV training, HW satisfaction), per province
A12: Annex 3b-HEALTH WORKERS - FAC | B12: Detailed overview of the scores for non-QQM indicators on Staffing (Salary payment, Health staff availability, GBV training, HW satisfaction), per health facility
A13: Annex 4a-MSS - PROV'!A1 | B13: Detailed overview of the scores for Minimum Standard of Services for health facilities not covered by QQM ( i.e SHC, RH/PH), per province
A14: Annex 4b-MSS - FAC'!A1 | B14: Detailed overview of the scores for Minimum Standard of Services for health facilities not covered by QQM ( i.e SHC, RH/PH), per health facility

Sheet Indicator list
A1: Overview of indicators by assessment
A2: # indicator | B2: Indicator Name | C2: Sub-indicator / Description | D2: Max Points (YES) | E2: Applicable at HFs
A3: QQM Structural Quality - Domain 1: General Management
A4: SQ 1.1 | B4: Presence of map of health facility catchment area | C4: A visually represented health map is displayed on the notice board of a health facility. The map includes population data, details of other health facilities in the area, villages, main roads, natural barriers, special points and distance (in kms) and a legend/key showing specific age group population adjusted yearly (<1, <5, WCBA). | D4: 0.5 | E4: BHC, CHC, DH
A5: SQ 1.2 | B5: Proper filing system | C5: 1.2.1 In a filing cabinet/shelf/cupboard, in the designated service, and accessible by the officer on duty (except individual staff files) | D5: 0.5 | E5: BHC, CHC, DH
C6: 1.2.2 Minimum documents to be filled in the Administrative office (i) HMIS and (ii) clinic visit book | D6: 0.5 | E6: BHC, CHC, DH
C7: 1.2.3 (iii)Attendance sheet and (iv) monthly, quarterly and annual activity plans and (v) staff meeting notebook | D7: 0.5 | E7: BHC, CHC, DH
C8: 1.2.4 (vi) Financial file and (vii) community contribution register | D8: 0.5 | E8: BHC, CHC, DH
C9: 1.2.5 Minimum documents to be filled include CHS room: (ix) CHW supervision visit book; (x) clinic health committee meeting minutes | D9: 0.5 | E9: BHC, CHC, DH
A10: SQ 1.3 | B10: Staff duty roster | C10: The staff duty roster is regularly updated and prominently displayed to both staff and patients. The roster includes the schedule for the current month, the assigned duties of each staff member and the phone numbers of on-duty staff. | D10: 1 | E10: BHC, CHC, DH
A11: SQ 1.4 | B11: Technical meetings | C11: Technical Meetings (Management Committee Meetings & Clinical Staff Meetings) are scheduled on a monthly basis. QI committee meetings can alternate with clinical staff meetings; with 2 weeks between meetings. Minutes are taken during each meeting and include the date of the meeting, progress updates on the implementation of previous recommendations or actions, a list of new recommendations or decisions, and the chairman's signature. Records include three complete Clinical Staff Meetings and one quarterly Management Committee Meeting with detailed minutes. | D11: 4 | E11: BHC, CHC, DH
A12: SQ 1.5 | B12: Standard referral sheets | C12: At least 10 (empty) standard referral sheets are present during the evaluation | D12: 1 | E12: BHC, CHC, DH
A13: SQ 1.6 | B13: Availability of dedicated mobile phone for communication between health facility and general hospital | C13: A functional and charged mobile phone with a minimum call credit of AFS200. At minimum, the phone must store contact details of the Medical Director of the District Hospital, health facility staff, other Health Facility in-charges within the district, district health department, and the SP contact. | D13: 1 | E13: BHC, CHC, DH
A14: SQ 1.7 | B14: HMIS reports (sent to SP offices and MoPH) | C14: The transmission of HMIS reports occurs on a monthly basis, and a signed receipt of acknowledgement, both from the SP provincial offices and the MoPH is available. | D14: 1 | E14: BHC, CHC, DH
A15: SQ 1.8 | B15: HMIS reports (assessed concerning priority problems) | C15: Each quarter, four priority health problems are monitored and the data in the report has been updated until the month preceding the supervisor's visit. Additionally, the report includes a graphical representation of the health facility's quality score (presented in an "all or nothing" format). This score is derived from a monthly summary of the health problem classifications recorded in the General register at the end of each month. | D15: 1 | E15: BHC, CHC, DH
A16: SQ 1.9 | B16: Health Shura meetings | C16: Health Shura meetings are conducted on a monthly basis and meeting minutes are available. The monthly minutes include (i) the date of the meeting; (ii) a signed list of participants; (iii) follow-up of decisions taken during the previous meeting; (iv) a list of developed recommendations or decisions made; (v) signature of the chairman. | D16: 2 | E16: BHC, CHC, DH
A17: QQM Structural Quality - Domain 2: Hygiene
A18: SQ 2.1 | B18: Fence health facility available and well-maintained | C18: There is fencing or a wall (at least 1.5m in height) in good condition (no cracks) around the area of the health facility that can be closed at night (except riverine areas) | D18: 1 | E18: BHC, CHC, DH
A19: SQ 2.2 | B19: Garbage bin | C19: The courtyard has a garbage bin with a lid that is easily accessible to clients, and it is not full at the time of the evaluation. | D19: 1 | E19: BHC, CHC, DH
A20: SQ 2.3 | B20: Latrines/toilets | C20: 2.3.1 At least four water closet functional latrines/toilets (either the flushable squatting closet or the sitting closet) two for staff: Male and female, two for patients: Male and female. Toilets have a written and a pictorial sign. | D20: 1 | E20: BHC, CHC, DH
C21: 2.3.2 Floor without fissures | D21: 0.5 | E21: BHC, CHC, DH
C22: 2.3.3 Recently cleaned without visible fecal matter | D22: 0.5 | E22: BHC, CHC, DH
C23: 2.3.4 Door lockable from the inside, ceiling and super structure with roofing, without flies and no smell | D23: 0.5 | E23: BHC, CHC, DH
C24: 2.3.5 Hand hygiene/ sinks are located at the toilets AND running water is available (either sourced from a container or from piped water supply) AND soap or liquid soap, or detergent available at the sink. | D24: 0.5 | E24: BHC, CHC, DH
A25: SQ 2.4 | B25: Showers | C25: 2.4.1 At least two bathing facilities; one for men one for women (with floor without fissures, Door lockable from the inside, super structure with roofing) (in case of BHC one bathing facility (for women only); in case of CHC at least two; one for men and one for women) | D25: 1 | E25: BHC, CHC, DH
C26: 2.4.2 Bathing facility with running water, or container with at the least 20 L of water | D26: 0.5 | E26: BHC, CHC, DH
C27: 2.4.3 Evacuation of the waste water in a sanitation pit | D27: 0.5 | E27: BHC, CHC, DH
A28: SQ 2.5 | B28: Waste pit | C28: 2.5.1 Waste disposal pit minimum 4 meters deep, lined with clay, concrete or brick or plastic, it is fenced and has a bright flag | D28: 12 | E28: BHC, CHC, DH
C29: 2.5.2 The waste pit is a minimum of 15 meters from the health facility, minimum of 50 meters from a household, and 100 meters from a water source except in cases where the available surface area does not allow for these distances | E29: BHC, CHC, DH
C30: 2.5.3 Health Care Waste is not visible (covered by at the least 10 cm of soil or lime) | E30: BHC, CHC, DH
C31: 2.5.4 The health facility maintains a register indicating the date of the creation of the pit(s), and the location (s) | E31: BHC, CHC, DH
A32: SQ 2.6 | B32: Courtyard clean | D32: 1 | E32: BHC, CHC, DH
A33: SQ 2.7 | B33: Sterilization | C33: 2.7.1 Sterilizer functional (eg Autoclave) | D33: 3 | E33: BHC, CHC, DH
C34: 2.7.2 Sterilization protocol available and followed (medical personnel present can explain the protocol or demonstrate the process). When explaining the staff should at the least cover: (i) how items are arranged/packed; (ii) explain sterilization time for packed and unpacked items, and (iii) how to unload the items from the sterilizer | E34: BHC, CHC, DH
A35: SQ 2.8 | B35: Hygienic conditions assured during wound dressing and injections | C35: 2.8 1 Yellow and Red Bins for medical waste with lid and foot pedal, lined with bag and not full | D35: 2 | E35: BHC, CHC, DH
C36: 2.8.2 Security box for needles well positioned, and used (and not full) | E36: BHC, CHC, DH
C37: 2.8.3 Needle cutter available and used | E37: BHC, CHC, DH
C38: 2.8.4 Container/bowl with lid containing disinfectant used for putting used instruments | E38: BHC, CHC, DH
A39: SQ 2.9 | B39: Disposal of Health Care Waste | C39: Waste is segregated into three bin categories for proper disposal in accordance with national norms. None of the bins should be full or over-flowing. i) Non-contaminated waste, which includes general or municipal waste such as food items, carton boxes, wrappings, and garbage are placed in lined Black Bins equipped with lids and foot pedals and the waste bin is not full; and, ii) Contaminated health care waste, which includes infectious hazardous materials like used medical equipment, linens, gauze, syringes, catheter, iv cannula, gloves, serum bottles, and more are placed in cellophane-lined Yellow Bins with lids and foot pedals; and, iii) Organic health care waste including body parts, placenta, removed teeth, body fluids, suction machine secretions, expired blood, and other biohazardous materials are placed in cellophane-lined Red Bins with lids and foot pedals; and, iv) Availability of proper protective gear, including caps, masks, gumboots or enclosed shoes, plastic aprons, and thick plastic/rubber gloves. | D39: 6 | E39: BHC, CHC, DH
A40: SQ 2.1 | B40: COVID-19 prevention | C40: 2.10.1 i) Masks are available and used by staff ii) Alcohol handwashing solution is available for staff and patients in at the least (i) OPD and (ii) MCH section and (iii) EPI iii) COVID-19 prevention posters visible for patients in waiting room for OPD, and consultation room, and MCH section, and EPI section | D40: 3 | E40: BHC, CHC, DH
...

Sheet 1-QQM_SUMMARY_SHEET
A1: Province | B1: Service provider | D1: QQM - Structural indicators - HER2 R1 - January to March 2024 | P1: QQM - Outcome quality - HER2 R1 - January to March 2024 | T1: QQM - Content of care - HER2 R1 - January to March 2024 | V1: QQM Score
C2: Funder | D2: Domain 1: General Management | E2: Domain 2: Hygiene | F2: Domain 3: OPD / Curative Consultations | G2: Domain 4: Family planning | H2: Domain 5: Laboratory | I2: Domain 6: Essential Drugs Management | J2: Domain 7: Tracer drugs | K2: Domain 8: Maternity | L2: Domain 9: EPI | M2: Domain 10: Antenatal Care | N2: Structural indicators score | P2: Exit interview with caregiver of a sick child under 5 | Q2: Exit interview Family Planning | R2: Outcome quality score
A3: Badakhshan | B3: AKDN | C3: WB | D3: 0.797619 | E3: 0.3406863 | F3: 0.5113636 | G3: 0.7318841 | H3: 0.8333333 | I3: 0.551282 | J3: 0.0108696 | K3: 0.7183908 | L3: 0.7962963 | M3: 0.5 | N3: 0.4405819 | P3: 0.438125 | Q3: 0.7271875 | R3: 0.5826563 | T3: 0.3346094 | V3: =(0.4*N3)+(0.2*R3)+(0.4*T3) -> 0.42660778 | W3: WB | X3: 0.48
A4: Badghis | B4: SAF | C4: ADB | D4: 0.6607143 | E4: 0.5919118 | F4: 0.78125 | G4: 0.4673913 | H4: 0.6333333 | I4: 0.6346154 | J4: 0.0119565 | K4: 0.7413793 | L4: 0.8240741 | M4: 0.8461539 | N4: 0.5010432 | P4: 0.412 | Q4: 0.6615 | R4: 0.53675 | T4: 0.391875 | V4: =(0.4*N4)+(0.2*R4)+(0.4*T4) -> 0.46451728
A5: Baghlan | B5: AKDN | C5: WB | D5: 0.7738096 | E5: 0.3014706 | F5: 0.7556818 | G5: 0.6884058 | H5: 0.8266667 | I5: 0.5 | J5: 0 | K5: 0.7873563 | L5: 0.8518519 | M5: 0.7884616 | N5: 0.4774841 | P5: 0.478 | Q5: 0.778 | R5: 0.628 | T5: 0.532375 | V5: =(0.4*N5)+(0.2*R5)+(0.4*T5) -> 0.52954364
A6: Balkh | B6: BDN | C6: WB | D6: 0.9107143 | E6: 0.6691176 | F6: 0.7784091 | G6: 0.8782609 | H6: 1 | I6: 0.6923077 | J6: 0.15 | K6: 0.837931 | L6: 0.9481481 | M6: 0.8307692 | N6: 0.6181138 | P6: 0.5036842 | Q6: 0.6626923 | R6: 0.5682812 | T6: 0.425 | V6: =(0.4*N6)+(0.2*R6)+(0.4*T6) -> 0.53090176
A7: Bamyan | B7: AKDN | C7: WB | D7: 0.9214286 | E7: 0.8352941 | F7: 0.6136364 | G7: 0.6434783 | H7: 0.9666666 | I7: 0.4307692 | J7: 0.0286957 | K7: 0.7862069 | L7: 0.9703704 | M7: 0.5923077 | N7: 0.5108982 | P7: 0.4836363 | Q7: 0.7704545 | R7: 0.6270455 | T7: 0.5307955 | V7: =(0.4*N7)+(0.2*R7)+(0.4*T7) -> 0.54208658
A8: Daykundi | B8: MOVE | C8: ADB | D8: 0.5446429 | E8: 0.5441176 | F8: 0.4346591 | G8: 0.5108696 | H8: 0.6666667 | I8: 0.5096154 | J8: 0 | K8: 0.7068965 | L8: 0.7962963 | M8: 0.6923077 | N8: 0.4129616 | P8: 0.4145454 | Q8: 0.6318182 | R8: 0.5231818 | T8: 0.57 | V8: =(0.4*N8)+(0.2*R8)+(0.4*T8) -> 0.497821
A9: Farah | B9: JACK | C9: ADB | D9: 0.5928571 | E9: 0.4 | F9: 0.5590909 | G9: 0.5913044 | H9: 0.85 | I9: 0.6769231 | J9: 0.0313043 | K9: 0.9379311 | L9: 0.8962963 | M9: 0.8846154 | N9: 0.5037647 | P9: 0.4445454 | Q9: 0.82 | R9: 0.6322727 | T9: 0.4432954 | V9: =(0.4*N9)+(0.2*R9)+(0.4*T9) -> 0.50527858
A10: Faryab | B10: SAF | C10: WB | D10: 0.4598214 | E10: 0.1856618 | F10: 0.5426136 | G10: 0.3695652 | H10: 0.6933333 | I10: 0.3990385 | J10: 0 | K10: 0.6637931 | L10: 0.712963 | M10: 0.7403846 | N10: 0.3571693 | P10: 0.37 | Q10: 0.7622222 | R10: 0.5234783 | T10: 0.4180435 | V10: =(0.4*N10)+(0.2*R10)+(0.4*T10) -> 0.41478078
A11: Ghazni | B11: JACK | C11: WB | D11: 0.4892857 | E11: 0.2882353 | F11: 0.7511364 | G11: 0.4 | H11: 0.7333333 | I11: 0.5692308 | J11: 0.0247826 | K11: 0.6586207 | L11: 0.7296296 | M11: 0.6115385 | N11: 0.4263189 | P11: 0.554375 | Q11: 0.7303333 | R11: 0.6395161 | T11: 0.2674194 | V11: =(0.4*N11)+(0.2*R11)+(0.4*T11) -> 0.40539854
A12: Ghor | B12: BARAN | C12: ADB | D12: 0.6428571 | E12: 0.5294118 | F12: 0.53125 | G12: 0.6413044 | H12: 0.8444445 | I12: 0.5192308 | J12: 0.0891304 | K12: 0.75 | L12: 0.9074074 | M12: 0.5961539 | N12: 0.4829035 | P12: 0.5136364 | Q12: 0.8385 | R12: 0.6683334 | T12: 0.465625 | V12: =(0.4*N12)+(0.2*R12)+(0.4*T12) -> 0.51307808
A13: Helmand | B13: OHPM | C13: ADB | D13: 0.4007936 | E13: 0.2287582 | F13: 0.4166667 | G13: 0.236715 | H13: 0.4888889 | I13: 0.3803419 | J13: 0 | K13: 0.5670498 | L13: 0.7078189 | M13: 0.3290598 | N13: 0.2979646 | P13: 0.33 | Q13: 0.5725 | R13: 0.4431667 | T13: 0.3081034 | V13: =(0.4*N13)+(0.2*R13)+(0.4*T13) -> 0.33106054
A14: Herat | B14: OHPM | C14: ADB | D14: 0.5714286 | E14: 0.425 | F14: 0.6 | G14: 0.3391304 | H14: 0.775 | I14: 0.5192308 | J14: 0.0186957 | K14: 0.7689655 | L14: 0.7555556 | M14: 0.5307692 | N14: 0.4243235 | P14: 0.38125 | Q14: 0.7346875 | R14: 0.5579687 | T14: 0.4176562 | V14: =(0.4*N14)+(0.2*R14)+(0.4*T14) -> 0.44838562
A15: Jawzjan | B15: SAF | C15: WB | D15: 0.7559524 | E15: 0.1593137 | F15: 0.6117424 | G15: 0.3695652 | H15: 0.5333334 | I15: 0.4423077 | J15: 0.0615942 | K15: 0.816092 | L15: 0.8271605 | M15: 0.6602564 | N15: 0.4133134 | P15: 0.512 | Q15: 0.729375 | R15: 0.5741072 | T15: 0.5695238 | V15: =(0.4*N15)+(0.2*R15)+(0.4*T15) -> 0.50795632
... A36: Zabul | B36: MOVE | C36: ADB | D36: 0.7142857 | E36: 0.3137255 | F36: 0.7291667 | G36: 0.8550724 | H36: 0.7333333 | I36: 0.551282 | J36: 0 | K36: 0.7873563 | L36: 0.7777778 | M36: 0.8589743 | N36: 0.4853157 | P36: 0.4625 | Q36: 0.698 | R36: 0.5933333 | T36: 0.503625 | V36: =(0.4*N36)+(0.2*R36)+(0.4*T36) -> 0.51424294
A37: National | D37: =AVERAGE(D3:D36) -> 0.66084808 | E37: =AVERAGE(E3:E36) -> 0.42530706 | F37: =AVERAGE(F3:F36) -> 0.61182625 | G37: =AVERAGE(G3:G36) -> 0.55774723 | H37: =AVERAGE(H3:H36) -> 0.7476634 | I37: =AVERAGE(I3:I36) -> 0.55344619 | J37: =AVERAGE(J3:J36) -> 0.039959609 | K37: =AVERAGE(K3:K36) -> 0.77407595 | ... N37: =AVERAGE(N3:N36) -> 0.46293384 | P37: =AVERAGE(P3:P36) -> 0.4462592 | Q37: =AVERAGE(Q3:Q36) -> 0.69068709 | R37: =AVERAGE(R3:R36) -> 0.55962186 | T37: =AVERAGE(T3:T36) -> 0.44756514 | V37: =(0.4*N37)+(0.2*R37)+(0.4*T37) -> 0.47612396
M38: P25 | N38: =_xlfn.PERCENTILE.INC(N3:N36,0.25) -> 0.40754067 | Q38: P25 | R38: =_xlfn.PERCENTILE.INC(R3:R36,0.25) -> 0.52465418 | S38: P25 | T38: =_xlfn.PERCENTILE.INC(T3:T36,0.25) -> 0.37017045 | U38: p25 | V38: =_xlfn.PERCENTILE.INC(V3:V36,0.25) -> 0.42671704
M39: P50 | N39: =_xlfn.PERCENTILE.INC(N3:N36,0.5) -> 0.4789024 | Q39: P50 | R39: =_xlfn.PERCENTILE.INC(R3:R36,0.5) -> 0.56312495 | S39: P50 | T39: =_xlfn.PERCENTILE.INC(T3:T36,0.5) -> 0.4341477 | U39: p50 | V39: =_xlfn.PERCENTILE.INC(V3:V36,0.5) -> 0.46916284

Sheet 2-QQM_BY ROUND
A1: Province | B1: Service provider | C1: Structural Quality | O1: Outcome Quality | AA1: Content Quality
C2: HER Round 4 [95%CI] | E2: HER2 Round 1 [95%CI] | G2: HER2 Round 2 [95%CI] | I2: HER2 Round 3 [95%CI] | K2: Difference HER R4 and HER2 R1 | L2: Difference HER2 R1 and HER2 R2 | M2: Difference HER2 R2 and HER2 R3 | O2: HER Round 4 [95%CI] | Q2: HER2 Round 1 [95%CI] | S2: HER2 Round 2 [95%CI] | U2: HER2 Round 3 [95%CI] | W2: Difference HER R4 and HER2 R1 | X2: Difference HER2 R1 and HER2 R2 | Y2: Difference HER2 R2 and HER2 R3 | AA2: HER Round 4 [95%CI] | AC2: HER2 Round 1 [95%CI] | AE2: HER2 Round 2 [95%CI] | AG2: HER2 Round 3 [95%CI] | AI2: Difference HER R4 and HER2 R1 | AJ2: Difference HER2 R1 and HER2 R2 | AK2: Difference HER2 R2 and HER2 R3
A3: Badakhshan | B3: AKDN | C3: 0.463 | D3: [41,3% - 53,7%] | E3: 0.441 | F3: [40,2% - 48,1%] | K3: -0.022 | O3: 0.668 | P3: [62,9% - 70,6%] | Q3: 0.583 | R3: [52,6% - 64,3%] | W3: -0.085 | AA3: 0.346 | AB3: [29,2% - 40%] | AC3: 0.335 | AD3: [27,5% - 40,2%] | AI3: -1,1%**
A4: Badghis | B4: SAF | C4: 0.319 | D4: [24,2% - 39,8%] | E4: 0.499 | F4: [37,4% - 63,7%] | K4: 0.18 | O4: 0.579 | P4: [53,4% - 62,6%] | Q4: 0.537 | R4: [42,3% - 62%] | W4: -0.042 | AA4: 0.262 | AB4: [21,2% - 31,1%] | AC4: 0.392 | AD4: [27,5% - 53,3%] | AI4: 0.13
A5: Baghlan | B5: AKDN | C5: 0.355 | D5: [29,2% - 41,9%] | E5: 0.477 | F5: [42,2% - 53%] | K5: 12,2%* | O5: 0.635 | P5: [59,8% - 66,9%] | Q5: 0.628 | R5: [57,1% - 68,6%] | W5: -,7%** | AA5: 0.245 | AB5: [16,7% - 32,6%] | AC5: 0.532 | AD5: [45,8% - 60,4%] | AI5: 0.287
A6: Balkh | B6: BDN | C6: 0.463 | D6: [42,3% - 50,4%] | E6: 0.616 | F6: [55,3% - 69,1%] | K6: 15,4%*** | O6: 0.598 | P6: [55,5% - 64,3%] | Q6: 0.568 | R6: [52,5% - 61,1%] | W6: -0.03 | AA6: 0.471 | AB6: [40,9% - 52,4%] | AC6: 0.425 | AD6: [38,4% - 47,6%] | AI6: -4,6%***
A7: Bamyan | B7: AKDN | C7: 0.456 | D7: [36,5% - 55,6%] | E7: 0.509 | F7: [43,8% - 58,2%] | K7: 0.053 | O7: 0.67 | P7: [64,1% - 70,1%] | Q7: 0.627 | R7: [57,6% - 68,5%] | W7: -4,3%* | AA7: 0.32 | AB7: [26,7% - 37,5%] | AC7: 0.531 | AD7: [45,8% - 59,5%] | AI7: 0.21
A8: Daykundi | B8: MOVE | C8: 0.428 | D8: [32,9% - 51,3%] | E8: 0.412 | F8: [34,5% - 47,9%] | K8: -0.017 | O8: 0.617 | P8: [57,9% - 64,9%] | Q8: 0.523 | R8: [49,3% - 55,2%] | W8: -0.093 | AA8: 0.354 | AB8: [28,4% - 44%] | AC8: 0.57 | AD8: [49,6% - 64,5%] | AI8: 0.216
A9: Farah | B9: JACK | C9: 0.365 | D9: [30,9% - 42,1%] | E9: 0.504 | F9: [47,8% - 52,7%] | K9: 0.139 | O9: 0.704 | P9: [65,4% - 74,5%] | Q9: 0.632 | R9: [60,5% - 66,2%] | W9: -7,1%** | AA9: 0.193 | AB9: [14,7% - 24,3%] | AC9: 0.443 | AD9: [42,5% - 46,4%] | AI9: 25,1%*
A10: Faryab | B10: SAF | C10: 0.373 | D10: [33,4% - 40,6%] | E10: 0.356 | F10: [28,8% - 42,4%] | K10: -0.018 | O10: 0.656 | P10: [60,6% - 70,8%] | Q10: 0.523 | R10: [40,9% - 58,5%] | W10: -0.132 | AA10: 0.308 | AB10: [25,8% - 35,8%] | AC10: 0.418 | AD10: [33,1% - 48%] | AI10: 0.11
A11: Ghazni | B11: JACK | C11: 0.38 | D11: [34,9% - 41,2%] | E11: 0.425 | F11: [37,9% - 48,5%] | K11: 0.045 | O11: 0.646 | P11: [60% - 69%] | Q11: 0.64 | R11: [61,7% - 66%] | W11: -0.006 | AA11: 0.28 | AB11: [24,3% - 32,2%] | AC11: 0.267 | AD11: [24,2% - 30%] | AI11: -0.013
A12: Ghor | B12: BARAN | C12: 0.399 | D12: [36,8% - 43,1%] | E12: 0.483 | F12: [37,1% - 62,9%] | K12: 8,4%* | O12: 0.585 | P12: [55,3% - 61,8%] | Q12: 0.668 | R12: [59,8% - 72,8%] | W12: 0.083 | AA12: 0.446 | AB12: [39,3% - 49,9%] | AC12: 0.466 | AD12: [35,9% - 56,7%] | AI12: 0.02
A13: Helmand | B13: OHPM | C13: 0.272 | D13: [22% - 32,7%] | E13: 0.296 | F13: [22,3% - 36,9%] | K13: 2,4%* | O13: 0.532 | P13: [49,2% - 57,5%] | Q13: 0.443 | R13: [37% - 51,2%] | W13: -0.089 | AA13: 0.263 | AB13: [22,6% - 30,3%] | AC13: 0.308 | AD13: [25,7% - 38,7%] | AI13: 4,5%*
A14: Herat | B14: OHPM | C14: 0.417 | D14: [38,7% - 44,4%] | E14: 0.423 | F14: [38,3% - 45,4%] | K14: 0.007 | O14: 0.595 | P14: [55,1% - 64,3%] | Q14: 0.558 | R14: [49,2% - 62,6%] | W14: -0.037 | AA14: 0.373 | AB14: [31,7% - 43,3%] | AC14: 0.418 | AD14: [37,1% - 46,3%] | AI14: 4,5%*
A15: Jawzjan | B15: SAF | C15: 0.582 | D15: [52,4% - 64,4%] | E15: 0.413 | F15: [37,2% - 45,1%] | K15: -16,9%*** | O15: 0.669 | P15: [61,6% - 72,2%] | Q15: 0.574 | R15: [53,6% - 64,7%] | W15: -0.094 | AA15: 0.489 | AB15: [38,3% - 60,6%] | AC15: 0.57 | AD15: [45,9% - 68,9%] | AI15: 8%***
A16: Kabul | B16: AKDN | C16: 0.504 | D16: [45,1% - 55,2%] | E16: 0.512 | F16: [47% - 55,2%] | K16: 0.008 | O16: 0.64 | P16: [59,4% - 67,4%] | Q16: 0.553 | R16: [49,9% - 60,4%] | W16: -0.086 | AA16: 0.357 | AB16: [30,6% - 41,6%] | AC16: 0.516 | AD16: [44,1% - 58,9%] | AI16: 0.159
A17: Kandahar | B17: JACK | C17: 0.298 | D17: [26% - 33,3%] | E17: 0.366 | F17: [33,2% - 39,3%] | K17: 0.069 | O17: 0.545 | P17: [48,6% - 59,6%] | Q17: 0.505 | R17: [45% - 56%] | W17: -0.04 | AA17: 0.263 | AB17: [21% - 32,2%] | AC17: 0.275 | AD17: [23,7% - 31,5%] | AI17: 1,2%*
A18: Kapisa | B18: OHPM | C18: 0.394 | D18: [36,4% - 41,7%] | E18: 0.406 | F18: [36% - 45,2%] | K18: 1,2%** | O18: 0.678 | P18: [61,8% - 72,7%] | Q18: 0.485 | R18: [42,9% - 53,8%] | W18: -0.194 | AA18: 0.431 | AB18: [38,9% - 46,7%] | AC18: 0.541 | AD18: [42% - 65,8%] | AI18: 0.111
A19: Khost | B19: HNTPO | C19: 0.368 | D19: [33% - 40,1%] | E19: 0.599 | F19: [57,2% - 63%] | K19: 0.231 | O19: 0.586 | P19: [57,2% - 59,9%] | Q19: 0.573 | R19: [49,6% - 64,5%] | W19: -1,2%*** | AA19: 0.219 | AB19: [17,6% - 25,7%] | AC19: 0.608 | AD19: [50,7% - 69,7%] | AI19: 38,9%*
A20: Kunar | B20: HNTPO | C20: 0.512 | D20: [46,3% - 57,6%] | E20: 0.633 | F20: [58,8% - 69,2%] | K20: 0.121 | O20: 0.525 | P20: [47,4% - 57,7%] | Q20: 0.66 | R20: [57,3% - 73,4%] | W20: 13,5%*** | AA20: 0.382 | AB20: [28,9% - 47,7%] | AC20: 0.657 | AD20: [51,7% - 79%] | AI20: 27,4%***
A21: Kunduz | B21: JACK | C21: 0.332 | D21: [28,5% - 37,5%] | E21: 0.48 | F21: [44,5% - 51,7%] | K21: 0.148 | O21: 0.502 | P21: [46,1% - 54,8%] | Q21: 0.497 | R21: [43,9% - 56,2%] | W21: -0.006 | AA21: 0.237 | AB21: [20,8% - 26,6%] | AC21: 0.33 | AD21: [28,2% - 39,4%] | AI21: 0.093
A22: Laghman | B22: HNTPO | C22: 0.647 | D22: [58,7% - 69,3%] | E22: 0.676 | F22: [56,9% - 78,3%] | K22: 2,9%*** | O22: 0.542 | P22: [48% - 60,6%] | Q22: 0.597 | R22: [45,4% - 73,1%] | W22: 5,5%* | AA22: 0.484 | AB22: [41,1% - 55,8%] | AC22: 0.671 | AD22: [58,8% - 76%] | AI22: 18,7%***
A23: Logar | B23: CAF | C23: 0.374 | D23: [34,1% - 40%] | E23: 0.574 | F23: [51,8% - 63,5%] | K23: 20,1%*** | O23: 0.638 | P23: [57,9% - 69,2%] | Q23: 0.615 | R23: [58,3% - 65,1%] | W23: -0.023 | AA23: 0.473 | AB23: [38,7% - 54,2%] | AC23: 0.633 | AD23: [57,2% - 68,9%] | AI23: 16%***
A24: Nangarhar | B24: JACK | C24: 0.421 | D24: [36,8% - 47,2%] | E24: 0.49 | F24: [44,3% - 54,3%] | K24: 0.069 | O24: 0.53 | P24: [49,7% - 57,4%] | Q24: 0.554 | R24: [49,2% - 61,7%] | W24: 0.024 | AA24: 0.275 | AB24: [22,4% - 33,5%] | AC24: 0.3 | AD24: [23,7% - 35,4%] | AI24: 0.025
A25: Nimroz | B25: RI-MRCA | C25: 0.378 | D25: [30,4% - 44,6%] | E25: 0.607 | F25: [48,9% - 70,5%] | K25: 0.229 | O25: 0.578 | P25: [53,7% - 61,9%] | Q25: 0.608 | R25: [53,6% - 67,2%] | W25: 0.029 | AA25: 0.226 | AB25: [18,3% - 27,3%] | AC25: 0.566 | AD25: [41,9% - 71,6%] | AI25: 0.34
A26: Nuristan | B26: AADA | C26: 0.543 | D26: [51% - 57,1%] | E26: 0.283 | F26: [24,8% - 30,8%] | K26: -26%*** | O26: 0.659 | P26: [59,9% - 71,6%] | Q26: 0.328 | R26: [28,7% - 38%] | W26: -0.331 | AA26: 0.306 | AB26: [23,4% - 37,7%] | AC26: 0.239 | AD26: [18,6% - 28,4%] | AI26: -6,8%*
A27: Paktika | B27: OHPM | C27: 0.381 | D27: [31,2% - 44,1%] | E27: 0.48 | F27: [42,4% - 53,6%] | K27: 0.099 | O27: 0.723 | P27: [69,1% - 76%] | Q27: 0.616 | R27: [56% - 66,8%] | W27: -10,7%*** | AA27: 0.251 | AB27: [19,4% - 30%] | AC27: 0.371 | AD27: [30,9% - 43,4%] | AI27: 0.119
A28: Paktya | B28: AADA | C28: 0.357 | D28: [29,6% - 44,8%] | E28: 0.353 | F28: [32,5% - 37,7%] | K28: -0.004 | O28: 0.69 | P28: [66,6% - 71,8%] | Q28: 0.53 | R28: [49,4% - 56,4%] | W28: -16,1%* | AA28: 0.256 | AB28: [19% - 33,6%] | AC28: 0.403 | AD28: [32,9% - 48,4%] | AI28: 0.147
A29: Panjsher | B29: MOVE | C29: 0.366 | D29: [34% - 38,7%] | E29: 0.388 | F29: [36,8% - 41,5%] | K29: 0.022 | O29: 0.686 | P29: [66,4% - 71%] | Q29: 0.623 | R29: [57,8% - 65,6%] | W29: -0.063 | AA29: 0.286 | AB29: [26,8% - 30,6%] | AC29: 0.384 | AD29: [34,6% - 42,3%] | AI29: 9,8%***
A30: Parwan | B30: JACK | C30: 0.315 | D30: [25,4% - 38%] | E30: 0.275 | F30: [23,1% - 32,3%] | K30: -4%* | O30: 0.582 | P30: [52,3% - 63,3%] | Q30: 0.528 | R30: [46,6% - 58,1%] | W30: -0.054 | AA30: 0.217 | AB30: [17,3% - 27,3%] | AC30: 0.257 | AD30: [20,7% - 30,8%] | AI30: 0.04
A31: Samangan | B31: MMRCA | C31: 0.557 | D31: [51,8% - 59,8%] | E31: 0.48 | F31: [44,6% - 51,2%] | K31: -7,6%*** | O31: 0.64 | P31: [59,8% - 69,2%] | Q31: 0.589 | R31: [53,7% - 65,1%] | W31: -0.051 | AA31: 0.329 | AB31: [26,4% - 42%] | AC31: 0.371 | AD31: [29,6% - 44,5%] | AI31: 0.042
A32: Sar-e-Pul | B32: MMRCA | C32: 0.348 | D32: [31,4% - 38,6%] | E32: 0.434 | F32: [34,9% - 51,8%] | K32: 0.087 | O32: 0.579 | P32: [53,1% - 62,7%] | Q32: 0.535 | R32: [46,7% - 61%] | W32: -0.044 | AA32: 0.174 | AB32: [12,9% - 22,6%] | AC32: 0.37 | AD32: [28% - 45,5%] | AI32: 0.196
A33: Takhar | B33: AKDN | C33: 0.375 | D33: [33,1% - 41,6%] | E33: 0.528 | F33: [49% - 58,1%] | K33: 15,3%** | O33: 0.479 | P33: [42,8% - 55%] | Q33: 0.55 | R33: [47,1% - 63,5%] | W33: 0.071 | AA33: 0.317 | AB33: [27,3% - 37,1%] | AC33: 0.566 | AD33: [46,2% - 67,1%] | AI33: 25%*
A34: Uruzgan | B34: AHDS | C34: 0.303 | D34: [26,6% - 33,2%] | E34: 0.392 | F34: [36% - 42,7%] | K34: 8,9%* | O34: 0.552 | P34: [51,7% - 58,3%] | Q34: 0.508 | R34: [42,4% - 59,6%] | W34: -0.043 | AA34: 0.335 | AB34: [25,8% - 41,2%] | AC34: 0.458 | AD34: [36,6% - 54,7%] | AI34: 0.123
A35: Wardak | B35: SCA | C35: 0.435 | D35: [38,2% - 48,5%] | E35: 0.423 | F35: [32,3% - 52,2%] | K35: -0.012 | O35: 0.67 | P35: [62,8% - 71,4%] | Q35: 0.474 | R35: [39,4% - 53,6%] | W35: -0.196 | AA35: 0.39 | AB35: [31,5% - 47%] | AC35: 0.524 | AD35: [44,1% - 59,5%] | AI35: 0.135
A36: Zabul | B36: MOVE | C36: 0.182 | D36: [14,7% - 21,7%] | E36: 0.485 | F36: [39,7% - 54,5%] | K36: 30,3%*** | O36: 0.414 | P36: [32,3% - 49%] | Q36: 0.593 | R36: [49,2% - 68,6%] | W36: 0.18 | AA36: 0.107 | AB36: [8,3% - 12,8%] | AC36: 0.504 | AD36: [30,1% - 62,8%] | AI36: 39,6%**
A37: No star = not significant
A38: * = p-value <0.05
A39: ** = p-value <0.01
A40: *** = p-value <0.001

Sheet Annex 1a - Structural_PROV
A1: HER2 R1 QQM - Structural Indicators January to March 2024 | C1: National | G1: Badakhshan | H1: Badghis | I1: Baghlan | J1: Balkh | K1: Bamyan | L1: Daykundi | M1: Farah | N1: Faryab | O1: Ghazni | P1: Ghor | Q1: Helmand | R1: Herat | S1: Jawzjan | T1: Kabul | U1: Kandahar | V1: Kapisa | W1: Khost | X1: Kunar | Y1: Kunduz | Z1: Laghman | AA1: Logar | AB1: Nangarhar | AC1: Nimroz | AD1: Nuristan | AE1: Paktika | AF1: Paktya | AG1: Panjsher | AH1: Parwan | AI1: Samangan | AJ1: Sar_e_Pul | AK1: Takhar | AL1: Uruzgan | AM1: Wardak | AN1: Zabul
A2: Service provider | C2: Mean | D2: Median | E2: Min | F2: Max | G2: AKDN | H2: SAF | I2: AKDN | J2: BDN | K2: AKDN | L2: MOVE | M2: JACK | N2: SAF | O2: JACK | P2: BARAN | Q2: OHPM | R2: OHPM | S2: SAF | T2: AKDN | U2: JACK | V2: OHPM | W2: HNTPO | X2: HNTPO | Y2: JACK | Z2: HNTPO | AA2: CAF | AB2: JACK | AC2: RI-MRCA | AD2: AADA | AE2: OHPM | AF2: AADA | AG2: MOVE | AH2: JACK | AI2: MMRCA | AJ2: MMRCA | AK2: AKDN | AL2: AHDS | AM2: SCA | AN2: MOVE
A3: Sample information
A4: Number of BHC | G4: 4 | H4: 3 | I4: 3 | J4: 6 | K4: 3 | L4: 3 | M4: 2 | N4: 4 | O4: 5 | P4: 3 | Q4: 6 | R4: 5 | S4: 4 | T4: 6 | U4: 4 | V4: 4 | W4: 2 | X4: 3 | Y4: 4 | Z4: 3 | AA4: 5 | AB4: 9 | AC4: 4 | AD4: 2 | AE4: 3 | AF4: 4 | AG4: 2 | AH4: 5 | AI4: 4 | AJ4: 3 | AK4: 4 | AL4: 3 | AM4: 4 | AN4: 3
A5: Number of CHC | G5: 2 | H5: 1 | I5: 2 | J5: 3 | K5: 1 | L5: 1 | M5: 2 | N5: 3 | O5: 4 | P5: 0 | Q5: 2 | R5: 4 | S5: 1 | T5: 2 | U5: 3 | V5: 2 | W5: 3 | X5: 1 | Y5: 2 | Z5: 2 | AA5: 2 | AB5: 2 | AC5: 2 | AD5: 1 | AE5: 2 | AF5: 1 | AG5: 1 | AH5: 0 | AI5: 1 | AJ5: 1 | AK5: 2 | AL5: 1 | AM5: 1 | AN5: 2
A6: Number of DH | G6: 0 | H6: 0 | I6: 1 | J6: 1 | K6: 1 | L6: 0 | M6: 1 | N6: 1 | O6: 1 | P6: 1 | Q6: 1 | R6: 1 | S6: 1 | T6: 1 | U6: 1 | V6: 0 | W6: 0 | X6: 1 | Y6: 1 | Z6: 0 | AA6: 1 | AB6: 1 | AC6: 0 | AD6: 1 | AE6: 1 | AF6: 1 | AG6: 1 | AH6: 0 | AI6: 1 | AJ6: 1 | AK6: 1 | AL6: 1 | AM6: 0 | AN6: 1
A7: Domain 1: General Management | C7: 0.6608481 | D7: 0.6607143 | E7: 0.2053571 | F7: 0.9928572 | G7: 0.79761904 | H7: 0.66071427 | I7: 0.77380955 | J7: 0.91071427 | K7: 0.92142856 | L7: 0.54464287 | M7: 0.59285712 | N7: 0.45982143 | O7: 0.48928571 | P7: 0.64285713 | Q7: 0.40079364 | R7: 0.5714286 | S7: 0.75595236 | T7: 0.82539684 | U7: 0.5 | V7: 0.66071427 | W7: 0.87142855 | X7: 0.96428573 | Y7: 0.65306121 | Z7: 0.99285716 | AA7: 0.9285714 | AB7: 0.87797618 | AC7: 0.8035714 | AD7: 0.20535715 | AE7: 0.36904761 | AF7: 0.39880952 | AG7: 0.52678573 | AH7: 0.42857143 | AI7: 0.69047618 | AJ7: 0.75714284 | AK7: 0.71428573 | AL7: 0.42857143 | AM7: 0.63571429 | AN7: 0.71428573
A8: 1 | B8: Presence of map of health facility catchment area | C8: 0.3631536 | D8: 0.2916667 | E8: 0 | F8: 1 | G8: 0.16666667 | H8: 0.25 | I8: 0.5 | J8: 0.60000002 | K8: 0.80000001 | L8: 0 | M8: 0 | N8: 0 | O8: 0.2 | P8: 0.5 | Q8: 0.11111111 | R8: 0 | S8: 0.16666667 | T8: 0.77777779 | U8: 0.125 | V8: 0.33333334 | W8: 0.80000001 | X8: 0.80000001 | Y8: 1 | Z8: 0.80000001 | AA8: 0.75 | AB8: 0.33333334 | AC8: 0.83333331 | AD8: 0 | AE8: 0 | AF8: 0.16666667 | AG8: 0 | AH8: 0.40000001 | AI8: 0 | AJ8: 0.60000002 | AK8: 1 | AL8: 0 | AM8: 0 | AN8: 0.33333334
A9: 2 | B9: Proper filing system | C9: 0.8299393 | D9: 0.845 | E9: 0.45 | F9: 1 | G9: 0.96666664 | H9: 0.85000002 | I9: 0.69999999 | J9: 0.89999998 | K9: 0.83999997 | L9: 0.75 | M9: 0.92000002 | N9: 0.57499999 | O9: 0.86000001 | P9: 0.89999998 | Q9: 0.62222224 | R9: 0.95999998 | S9: 0.80000001 | T9: 1 | U9: 0.72500002 | V9: 0.69999999 | W9: 0.95999998 | X9: 1 | Y9: 0.88571429 | Z9: 1 | AA9: 1 | AB9: 0.98333335 | AC9: 0.93333334 | AD9: 0.44999999 | AE9: 0.73333335 | AF9: 0.66666669 | AG9: 0.75 | AH9: 0.72000003 | AI9: 0.93333334 | AJ9: 0.83999997 | AK9: 1 | AL9: 0.72000003 | AM9: 0.83999997 | AN9: 0.73333335
A10: 3 | B10: Staff duty roster | C10: 0.7503735 | D10: 0.8 | E10: 0 | F10: 1 | G10: 1 | H10: 1 | I10: 1 | J10: 0.89999998 | K10: 1 | L10: 1 | M10: 0.80000001 | N10: 0.25 | O10: 0.69999999 | P10: 1 | Q10: 0.55555558 | R10: 0.80000001 | S10: 0.5 | T10: 1 | U10: 0.5 | V10: 0.5 | W10: 0.80000001 | X10: 1 | Y10: 0.85714287 | Z10: 1 | AA10: 1 | AB10: 0.83333331 | AC10: 1 | AD10: 0 | AE10: 0.5 | AF10: 0.5 | AG10: 0.75 | AH10: 0.80000001 | AI10: 0.66666669 | AJ10: 0.80000001 | AK10: 1 | AL10: 0 | AM10: 1 | AN10: 0.5
A11: 4 | B11: Technical meetings | C11: 0.557884 | D11: 0.5178571 | E11: 0 | F11: 1 | G11: 0.79166669 | H11: 0.5 | I11: 0.75 | J11: 0.94999999 | K11: 1 | L11: 0.875 | M11: 0.40000001 | N11: 0.46875 | O11: 0.22499999 | P11: 0.375 | Q11: 0.1388889 | R11: 0.27500001 | S11: 0.875 | T11: 0.41666666 | U11: 0.4375 | V11: 0.75 | W11: 0.75 | X11: 1 | Y11: 0.53571427 | Z11: 1 | AA11: 0.96875 | AB11: 0.91666669 | AC11: 0.5 | AD11: 0 | AE11: 0.20833333 | AF11: 0 | AG11: 0.3125 | AH11: 0.30000001 | AI11: 0.625 | AJ11: 0.69999999 | AK11: 0.21428572 | AL11: 0.40000001 | AM11: 0.60000002 | AN11: 0.70833331
A12: 5 | B12: Standard referral sheets | C12: 0.9617647 | D12: 1 | E12: 0.75 | F12: 1 | G12: 1 | H12: 1 | I12: 1 | J12: 1 | K12: 1 | L12: 0.75 | M12: 1 | N12: 0.75 | O12: 1 | P12: 0.75 | Q12: 1 | R12: 0.89999998 | S12: 1 | T12: 1 | U12: 1 | V12: 0.83333331 | W12: 1 | X12: 1 | Y12: 1 | Z12: 1 | AA12: 1 | AB12: 0.91666669 | AC12: 1 | AD12: 1 | AE12: 1 | AF12: 1 | AG12: 1 | AH12: 1 | AI12: 1 | AJ12: 1 | AK12: 1 | AL12: 0.80000001 | AM12: 1 | AN12: 1
A13: 6 | B13: Availability of dedicated mobile phone for communication between health facility and general hospital | C13: 0.2656162 | D13: 0.1 | E13: 0 | F13: 1 | G13: 0.33333334 | H13: 0.25 | I13: 0.5 | J13: 0.69999999 | K13: 0.60000002 | L13: 0 | M13: 0 | N13: 0 | O13: 0 | P13: 0.5 | Q13: 0 | R13: 0 | S13: 0.33333334 | T13: 1 | U13: 0 | V13: 0 | W13: 0.60000002 | X13: 0.60000002 | Y13: 0 | Z13: 1 | AA13: 0.25 | AB13: 0.25 | AC13: 1 | AD13: 0 | AE13: 0 | AF13: 0 | AG13: 0 | AH13: 0 | AI13: 0 | AJ13: 0.2 | AK13: 0.71428573 | AL13: 0 | AM13: 0.2 | AN13: 0
A14: 7 | B14: HMIS reports (sent to SP offices and MoPH) | C14: 0.7720588 | D14: 0.8333333 | E14: 0 | F14: 1 | G14: 0.83333331 | H14: 0.75 | I14: 0.5 | J14: 1 | K14: 1 | L14: 0 | M14: 1 | N14: 0.75 | O14: 0.5 | P14: 0.75 | Q14: 0.66666669 | R14: 0.89999998 | S14: 0.66666669 | T14: 1 | U14: 0.5 | V14: 0.83333331 | W14: 1 | X14: 1 | Y14: 1 | Z14: 1 | AA14: 1 | AB14: 1 | AC14: 1 | AD14: 0.75 | AE14: 0 | AF14: 0.66666669 | AG14: 0.75 | AH14: 1 | AI14: 0.83333331 | AJ14: 1 | AK14: 1 | AL14: 0.40000001 | AM14: 0.2 | AN14: 1
A15: 8 | B15: HMIS reports (assessed concerning priority problems) | C15: 0.523296 | D15: 0.5833333 | E15: 0 | F15: 1 | G15: 0.66666669 | H15: 0 | I15: 0.83333331 | J15: 1 | K15: 0.80000001 | L15: 0 | M15: 0 | N15: 0.125 | O15: 0.30000001 | P15: 0.5 | Q15: 0.11111111 | R15: 0.30000001 | S15: 0.5 | T15: 1 | U15: 0.125 | V15: 0.83333331 | W15: 1 | X15: 1 | Y15: 0 | Z15: 1 | AA15: 1 | AB15: 1 | AC15: 0.83333331 | AD15: 0 | AE15: 0 | AF15: 0.33333334 | AG15: 0.75 | AH15: 0 | AI15: 0.66666669 | AJ15: 0.40000001 | AK15: 0.71428573 | AL15: 0.2 | AM15: 0.80000001 | AN15: 1
A16: 9 | B16: Health Shura meetings | C16: 0.7454015 | D16: 0.8166667 | E16: 0 | F16: 1 | G16: 0.83333331 | H16: 1 | I16: 1 | J16: 0.89999998 | K16: 1 | L16: 0.25 | M16: 0.80000001 | N16: 0.625 | O16: 0.60000002 | P16: 0.75 | Q16: 0.55555558 | R16: 0.80000001 | S16: 1 | T16: 1 | U16: 0.625 | V16: 0.66666669 | W16: 1 | X16: 1 | Y16: 0.71428573 | Z16: 1 | AA16: 1 | AB16: 1 | AC16: 0.83333331 | AD16: 0 | AE16: 0.5 | AF16: 0.66666669 | AG16: 0.5 | AH16: 0 | AI16: 0.83333331 | AJ16: 1 | AK16: 0.85714287 | AL16: 0.60000002 | AM16: 0.60000002 | AN16: 0.83333331
A17: Domain 2: Hygiene | C17: 0.4253071 | D17: 0.4161765 | E17: 0.0676471 | F17: 0.8794118 | G17: 0.34068626 | H17: 0.59191179 | I17: 0.30147058 | J17: 0.66911763 | K17: 0.83529413 | L17: 0.54411763 | M17: 0.40000001 | N17: 0.18566176 | O17: 0.28823531 | P17: 0.52941179 | Q17: 0.22875817 | R17: 0.42500001 | S17: 0.15931372 | T17: 0.48366013 | U17: 0.21139705 | V17: 0.28921568 | W17: 0.7352941 | X17: 0.73823529 | Y17: 0.37394959 | Z17: 0.87941176 | AA17: 0.53125 | AB17: 0.4240196 | AC17: 0.67647058 | AD17: 0.13235295 | AE17: 0.44362745 | AF17: 0.22794117 | AG17: 0.44117647 | AH17: 0.06764706 | AI17: 0.33578432 | AJ17: 0.42352942 | AK17: 0.52100843 | AL17: 0.30294117 | AM17: 0.40882352 | AN17: 0.3137255
A18: 1 | B18: Fence health facility available and well-maintained | C18: 0.8498483 | D18: 0.8452381 | E18: 0.5 | F18: 1 | G18: 0.66666669 | H18: 1 | I18: 0.83333331 | J18: 0.60000002 | K18: 0.80000001 | L18: 1 | M18: 1 | N18: 0.875 | O18: 0.80000001 | P18: 1 | Q18: 0.8888889 | R18: 1 | S18: 0.66666669 | T18: 0.66666669 | U18: 1 | V18: 1 | W18: 0.80000001 | X18: 1 | Y18: 0.85714287 | Z18: 1 | AA18: 1 | AB18: 0.83333331 | AC18: 1 | AD18: 0.5 | AE18: 1 | AF18: 0.83333331 | AG18: 0.75 | AH18: 0.80000001 | AI18: 0.83333331 | AJ18: 0.60000002 | AK18: 0.85714287 | AL18: 1 | AM18: 0.60000002 | AN18: 0.83333331
A19: 2 | B19: Garbage bin | C19: 0.709057 | D19: 0.75 | E19: 0 | F19: 1 | G19: 0.83333331 | H19: 0.75 | I19: 0.33333334 | J19: 0.60000002 | K19: 0.60000002 | L19: 0.5 | M19: 0.80000001 | N19: 0.25 | O19: 0.60000002 | P19: 0.75 | Q19: 0.8888889 | R19: 0.80000001 | S19: 0 | T19: 1 | U19: 1 | V19: 0.83333331 | W19: 0.80000001 | X19: 1 | Y19: 0.42857143 | Z19: 1 | AA19: 1 | AB19: 0.75 | AC19: 1 | AD19: 0.75 | AE19: 0.66666669 | AF19: 0.66666669 | AG19: 0.75 | AH19: 0.80000001 | AI19: 1 | AJ19: 0.40000001 | AK19: 0.85714287 | AL19: 0.2 | AM19: 1 | AN19: 0.5
A20: 3 | B20: Latrines/toilets | C20: 0.4236539 | D20: 0.4166667 | E20: 0.047619 | F20: 0.875 | G20: 0.52777779 | H20: 0.875 | I20: 0.11111111 | J20: 0.41666666 | K20: 0.26666668 | L20: 0.5 | M20: 0.86666667 | N20: 0.1875 | O20: 0.41666666 | P20: 0.25 | Q20: 0.42592594 | R20: 0.43333334 | S20: 0.25 | T20: 0.53703702 | U20: 0.45833334 | V20: 0.27777779 | W20: 0.36666667 | X20: 0.56666666 | Y20: 0.04761905 | Z20: 0.63333333 | AA20: 0.27083334 | AB20: 0.66666669 | AC20: 0.77777779 | AD20: 0.33333334 | AE20: 0.6111111 | AF20: 0.3611111 | AG20: 0.29166666 | AH20: 0.13333334 | AI20: 0.30555555 | AJ20: 0.36666667 | AK20: 0.5714286 | AL20: 0.33333334 | AM20: 0.46666667 | AN20: 0.5
A21: 4 | B21: Showers | C21: 0.5364175 | D21: 0.5388889 | E21: 0.05 | F21: 1 | G21: 0.5 | H21: 0.75 | I21: 0.375 | J21: 0.40000001 | K21: 0.80000001 | L21: 0.125 | M21: 0.80000001 | N21: 0.25 | O21: 0.22499999 | P21: 0.5 | Q21: 0.52777779 | R21: 0.67500001 | S21: 0.16666667 | T21: 0.58333331 | U21: 0.34375 | V21: 0.41666666 | W21: 0.55000001 | X21: 0.40000001 | Y21: 0.78571427 | Z21: 1 | AA21: 0.5625 | AB21: 0.66666669 | AC21: 0.91666669 | AD21: 0.375 | AE21: 0.875 | AF21: 0.41666666 | AG21: 0.6875 | AH21: 0.05 | AI21: 0.75 | AJ21: 0.64999998 | AK21: 0.71428573 | AL21: 0.64999998 | AM21: 0.25 | AN21: 0.5
A22: 5 | B22: Waste pit | C22: 0.2264706 | D22: 0 | E22: 0 | F22: 1 | G22: 0 | H22: 0.25 | I22: 0.33333334 | J22: 0.89999998 | K22: 1 | L22: 0.75 | M22: 0 | N22: 0 | O22: 0.1 | P22: 0.25 | Q22: 0 | R22: 0 | S22: 0 | T22: 0 | U22: 0 | V22: 0.16666667 | W22: 0.80000001 | X22: 0.60000002 | Y22: 0 | Z22: 1 | AA22: 0 | AB22: 0.25 | AC22: 0.5 | AD22: 0 | AE22: 0 | AF22: 0 | AG22: 0 | AH22: 0 | AI22: 0 | AJ22: 0.40000001 | AK22: 0 | AL22: 0.2 | AM22: 0.2 | AN22: 0
A23: 6 | B23: Courtyard clean | C23: 0.9221872 | D23: 1 | E23: 0.2 | F23: 1 | G23: 1 | H23: 1 | I23: 1 | J23: 0.89999998 | K23: 1 | L23: 1 | M23: 1 | N23: 0.625 | O23: 1 | P23: 1 | Q23: 0.8888889 | R23: 1 | S23: 0.66666669 | T23: 1 | U23: 1 | V23: 0.83333331 | W23: 1 | X23: 1 | Y23: 1 | Z23: 1 | AA23: 1 | AB23: 1 | AC23: 1 | AD23: 0.75 | AE23: 1 | AF23: 1 | AG23: 1 | AH23: 0.2 | AI23: 1 | AJ23: 1 | AK23: 0.85714287 | AL23: 0.80000001 | AM23: 1 | AN23: 0.83333331
A24: 7 | B24: Sterilization | C24: 0.5705182 | D24: 0.55 | E24: 0 | F24: 1 | G24: 0.83333331 | H24: 0.5 | I24: 0.5 | J24: 0.80000001 | K24: 1 | L24: 0.25 | M24: 0.80000001 | N24: 0.5 | O24: 0.2 | P24: 1 | Q24: 0.22222222 | R24: 0.60000002 | S24: 0.33333334 | T24: 0.77777779 | U24: 0 | V24: 0.5 | W24: 1 | X24: 1 | Y24: 0.71428573 | Z24: 0.80000001 | AA24: 1 | AB24: 0.83333331 | AC24: 1 | AD24: 0 | AE24: 0.16666667 | AF24: 0.66666669 | AG24: 0.5 | AH24: 0 | AI24: 0 | AJ24: 0.2 | AK24: 1 | AL24: 0.40000001 | AM24: 0.80000001 | AN24: 0.5
A25: 8 | B25: Hygienic condicitions assured during wound dressing and injections | C25: 0.4018091 | D25: 0.2928571 | E25: 0 | F25: 1 | G25: 0 | H25: 1 | I25: 0 | J25: 0.30000001 | K25: 1 | L25: 0 | M25: 0.60000002 | N25: 0.25 | O25: 0 | P25: 0 | Q25: 0.22222222 | R25: 0.60000002 | S25: 0 | T25: 0.66666669 | U25: 0.125 | V25: 0 | W25: 0.80000001 | X25: 0.80000001 | Y25: 0.2857143 | Z25: 1 | AA25: 0.75 | AB25: 0 | AC25: 0.66666669 | AD25: 0 | AE25: 0.66666669 | AF25: 0.16666667 | AG25: 1 | AH25: 0 | AI25: 0.83333331 | AJ25: 0.80000001 | AK25: 0.42857143 | AL25: 0 | AM25: 0.2 | AN25: 0.5
A26: 9 | B26: Disposal of Health Care Waste | C26: 0.510796 | D26: 0.55 | E26: 0 | F26: 1 | G26: 0.5 | H26: 0.75 | I26: 0.16666667 | J26: 0.40000001 | K26: 0.80000001 | L26: 0.75 | M26: 0.40000001 | N26: 0.125 | O26: 0.2 | P26: 1 | Q26: 0.22222222 | R26: 0.60000002 | S26: 0.16666667 | T26: 0.8888889 | U26: 0.25 | V26: 0.16666667 | W26: 0.80000001 | X26: 0.80000001 | Y26: 0.85714287 | Z26: 0.80000001 | AA26: 1 | AB26: 0.33333334 | AC26: 0.66666669 | AD26: 0 | AE26: 0.66666669 | AF26: 0 | AG26: 1 | AH26: 0 | AI26: 0.66666669 | AJ26: 0.40000001 | AK26: 0.85714287 | AL26: 0.2 | AM26: 0.60000002 | AN26: 0.33333334
A27: 10 | B27: COVID-19 prevention | C27: 0.4459851 | D27: 0.3333333 | E27: 0 | F27: 1 | G27: 0.33333334 | H27: 0.75 | I27: 0.16666667 | J27: 0.80000001 | K27: 0.60000002 | L27: 0 | M27: 0.2 | N27: 0.25 | O27: 0.89999998 | P27: 0.5 | Q27: 0.11111111 | R27: 0.80000001 | S27: 0.33333334 | T27: 0.66666669 | U27: 0.125 | V27: 0.33333334 | W27: 0.40000001 | X27: 1 | Y27: 0.2857143 | Z27: 0.60000002 | AA27: 0.875 | AB27: 0.33333334 | AC27: 0.5 | AD27: 0.25 | AE27: 1 | AF27: 0.33333334 | AG27: 0.25 | AH27: 0 | AI27: 0.16666667 | AJ27: 0.2 | AK27: 1 | AL27: 0.40000001 | AM27: 0.2 | AN27: 0.5
A28: Domain 3: OPD / Curative Consultations | C28: 0.6118262 | D28: 0.6170455 | E28: 0.2431818 | F28: 0.8409091 | G28: 0.51136363 | H28: 0.78125 | I28: 0.75568181 | J28: 0.77840906 | K28: 0.61363637 | L28: 0.43465909 | M28: 0.55909091 | N28: 0.54261363 | O28: 0.75113636 | P28: 0.53125 | Q28: 0.41666666 | R28: 0.60000002 | S28: 0.61174244 | T28: 0.72601008 | U28: 0.49005681 | V28: 0.66287881 | W28: 0.79772729 | X28: 0.84090906 | Y28: 0.54058445 | Z28: 0.84090906 | AA28: 0.77130681 | AB28: 0.73674244 | AC28: 0.71590906 | AD28: 0.34943181 | AE28: 0.73863637 | AF28: 0.52840906 | AG28: 0.30397728 | AH28: 0.24318182 | AI28: 0.657197 | AJ28: 0.59318179 | AK28: 0.62337661 | AL28: 0.40454546 | AM28: 0.62045455 | AN28: 0.72916669
A29: 1 | B29: Good conditions in waiting area | C29: 0.6560691 | D29: 0.75 | E29: 0 | F29: 1 | G29: 1 | H29: 0.75 | I29: 1 | J29: 0.69999999 | K29: 0 | L29: 0.5 | M29: 1 | N29: 0 | O29: 0.60000002 | P29: 0.5 | Q29: 0.66666669 | R29: 0.69999999 | S29: 0.83333331 | T29: 0.77777779 | U29: 0.5 | V29: 0.83333331 | W29: 0.60000002 | X29: 1 | Y29: 0.85714287 | Z29: 0.80000001 | AA29: 1 | AB29: 0.58333331 | AC29: 0.83333331 | AD29: 0.25 | AE29: 0.83333331 | AF29: 0 | AG29: 0.75 | AH29: 0 | AI29: 0.83333331 | AJ29: 0.40000001 | AK29: 0.5714286 | AL29: 1 | AM29: 0.80000001 | AN29: 0.83333331
A30: 2 | B30: Drugs which are available free of charge displayed to the public | C30: 0.5486111 | D30: 0.5777778 | E30: 0 | F30: 1 | G30: 0.66666669 | H30: 0.75 | I30: 1 | J30: 0.89999998 | K30: 0.60000002 | L30: 0.75 | M30: 0.40000001 | N30: 0.125 | O30: 0.60000002 | P30: 1 | Q30: 0.22222222 | R30: 0.1 | S30: 0.66666669 | T30: 0.55555558 | U30: 0.5 | V30: 0.5 | W30: 0.60000002 | X30: 0 | Y30: 1 | Z30: 1 | AA30: 0.75 | AB30: 1 | AC30: 1 | AD30: 0.5 | AE30: 0 | AF30: 0.5 | AG30: 0 | AH30: 0 | AI30: 0.83333331 | AJ30: 0.40000001 | AK30: 1 | AL30: 0 | AM30: 0.40000001 | AN30: 0.33333334
A31: 3 | B31: Waiting card (or token) system with numbers | C31: 0.7477241 | D31: 0.8 | E31: 0.2 | F31: 1 | G31: 1 | H31: 1 | I31: 1 | J31: 0.89999998 | K31: 1 | L31: 0.75 | M31: 0.80000001 | N31: 0.5 | O31: 0.89999998 | P31: 0.75 | Q31: 0.66666669 | R31: 0.89999998 | S31: 0.66666669 | T31: 1 | U31: 0.5 | V31: 0.5 | W31: 1 | X31: 1 | Y31: 0.71428573 | Z31: 1 | AA31: 0.375 | AB31: 0.75 | AC31: 1 | AD31: 0.5 | AE31: 0.83333331 | AF31: 0.66666669 | AG31: 0.25 | AH31: 0.80000001 | AI31: 0.83333331 | AJ31: 0.80000001 | AK31: 1 | AL31: 0.2 | AM31: 0.2 | AN31: 0.66666669
A32: 4 | B32: Consultation room in good condition | C32: 0.4412173 | D32: 0.5 | E32: 0 | F32: 0.9166667 | G32: 0.16666667 | H32: 0.91666669 | I32: 0.47222221 | J32: 0.73333335 | K32: 0.53333336 | L32: 0 | M32: 0.76666665 | N32: 0.5 | O32: 0.64999998 | P32: 0.25 | Q32: 0.14814815 | R32: 0.53333336 | S32: 0.5 | T32: 0.4074074 | U32: 0.14583333 | V32: 0.6111111 | W32: 0.56666666 | X32: 0.56666666 | Y32: 0.54761904 | Z32: 0.80000001 | AA32: 0.41666666 | AB32: 0.66666669 | AC32: 0.91666669 | AD32: 0 | AE32: 0.47222221 | AF32: 0.1388889 | AG32: 0.08333334 | AH32: 0 | AI32: 0.6111111 | AJ32: 0.53333336 | AK32: 0.2857143 | AL32: 0.1 | AM32: 0.43333334 | AN32: 0.52777779
A33: 5 | B33: Consultation room 24/7 light | C33: 0.8139822 | D33: 0.8333333 | E33: 0.4 | F33: 1 | G33: 0.66666669 | H33: 1 | I33: 0.83333331 | J33: 0.60000002 | K33: 0.80000001 | L33: 0.75 | M33: 1 | N33: 0.5 | O33: 0.89999998 | P33: 0.75 | Q33: 0.77777779 | R33: 0.89999998 | S33: 0.5 | T33: 1 | U33: 0.75 | V33: 1 | W33: 0.60000002 | X33: 1 | Y33: 0.85714287 | Z33: 1 | AA33: 0.75 | AB33: 0.91666669 | AC33: 1 | AD33: 0.75 | AE33: 0.83333331 | AF33: 1 | AG33: 0.75 | AH33: 0.40000001 | AI33: 1 | AJ33: 0.80000001 | AK33: 0.85714287 | AL33: 0.60000002 | AM33: 1 | AN33: 0.83333331
A34: 6 | B34: Consultations done by skilled staff | C34: 0.5623833 | D34: 0.5 | E34: 0 | F34: 1 | G34: 0.33333334 | H34: 0.5 | I34: 0.33333334 | J34: 0.60000002 | K34: 1 | L34: 0.5 | M34: 0.40000001 | N34: 0.375 | O34: 1 | P34: 0.25 | Q34: 0.22222222 | R34: 0.5 | S34: 0.5 | T34: 1 | U34: 0.375 | V34: 0.83333331 | W34: 0.80000001 | X34: 1 | Y34: 0.42857143 | Z34: 1 | AA34: 0.875 | AB34: 0.41666666 | AC34: 1 | AD34: 0.5 | AE34: 0.83333331 | AF34: 0.5 | AG34: 0.25 | AH34: 0 | AI34: 1 | AJ34: 0 | AK34: 0.42857143 | AL34: 0.60000002 | AM34: 0.60000002 | AN34: 0.16666667
A35: 7 | B35: Consulting staff well-dressed | C35: 0.8812383 | D35: 0.9166667 | E35: 0.5 | F35: 1 | G35: 1 | H35: 1 | I35: 0.91666669 | J35: 1 | K35: 1 | L35: 1 | M35: 1 | N35: 0.75 | O35: 1 | P35: 1 | Q35: 0.77777779 | R35: 1 | S35: 0.66666669 | T35: 0.94444442 | U35: 0.9375 | V35: 0.83333331 | W35: 0.89999998 | X35: 1 | Y35: 0.78571427 | Z35: 0.89999998 | AA35: 1 | AB35: 0.70833331 | AC35: 1 | AD35: 0.875 | AE35: 1 | AF35: 0.91666669 | AG35: 0.5 | AH35: 0.69999999 | AI35: 0.91666669 | AJ35: 0.69999999 | AK35: 1 | AL35: 0.80000001 | AM35: 0.60000002 | AN35: 0.83333331
A36: 8 | B36: Correct numbering of registers | C36: 0.8432657 | D36: 1 | E36: 0.2 | F36: 1 | G36: 0.5 | H36: 0.75 | I36: 1 | J36: 1 | K36: 0.60000002 | L36: 0.5 | M36: 1 | N36: 0.5 | O36: 1 | P36: 0.5 | Q36: 0.8888889 | R36: 0.89999998 | S36: 1 | T36: 1 | U36: 1 | V36: 1 | W36: 1 | X36: 1 | Y36: 0.85714287 | Z36: 1 | AA36: 0.875 | AB36: 0.75 | AC36: 1 | AD36: 1 | AE36: 1 | AF36: 1 | AG36: 0.25 | AH36: 0.2 | AI36: 1 | AJ36: 1 | AK36: 1 | AL36: 0.80000001 | AM36: 0.80000001 | AN36: 1
A37: 9 | B37: Service availability 24/7 | C37: 0.5333917 | D37: 0.5 | E37: 0.1666667 | F37: 1 | G37: 0.66666669 | H37: 0.75 | I37: 0.66666669 | J37: 0.89999998 | K37: 1 | L37: 0.75 | M37: 0.60000002 | N37: 0.25 | O37: 0.5 | P37: 0.25 | Q37: 0.22222222 | R37: 0.5 | S37: 0.16666667 | T37: 1 | U37: 0.625 | V37: 0.5 | W37: 0.80000001 | X37: 0.60000002 | Y37: 0.5714286 | Z37: 0.80000001 | AA37: 0.25 | AB37: 0.25 | AC37: 0.66666669 | AD37: 0.25 | AE37: 0.5 | AF37: 0.16666667 | AG37: 0.5 | AH37: 0.60000002 | AI37: 0.33333334 | AJ37: 0.2 | AK37: 1 | AL37: 0.40000001 | AM37: 0.40000001 | AN37: 0.5
A38: 10 | B38: Malaria protocol | C38: 0.5997549 | D38: 0.725 | E38: 0 | F38: 1 | G38: 0.5 | H38: 0.75 | I38: 0.83333331 | J38: 0.69999999 | K38: 0.2 | L38: 1 | M38: 0.2 | N38: 0.125 | O38: 0.40000001 | P38: 1 | Q38: 0.33333334 | R38: 0.89999998 | S38: 0.66666669 | T38: 1 | U38: 0.125 | V38: 1 | W38: 1 | X38: 1 | Y38: 0.42857143 | Z38: 0.80000001 | AA38: 0.875 | AB38: 0.83333331 | AC38: 0.83333331 | AD38: 0.25 | AE38: 1 | AF38: 0.83333331 | AG38: 0 | AH38: 0 | AI38: 0 | AJ38: 0.40000001 | AK38: 0.5714286 | AL38: 0.2 | AM38: 0.80000001 | AN38: 0.83333331
A39: 11 | B39: ARI WHO flow diagram | C39: 0.5004552 | D39: 0.5 | E39: 0 | F39: 1 | G39: 0.33333334 | H39: 1 | I39: 0.33333334 | J39: 0.5 | K39: 0.2 | L39: 0.25 | M39: 0.2 | N39: 0.25 | O39: 0.1 | P39: 0.5 | Q39: 0.33333334 | R39: 1 | S39: 0.33333334 | T39: 1 | U39: 0.125 | V39: 0.83333331 | W39: 1 | X39: 1 | Y39: 0.14285715 | Z39: 0.80000001 | AA39: 0.5 | AB39: 0.83333331 | AC39: 0.83333331 | AD39: 0 | AE39: 0.66666669 | AF39: 1 | AG39: 0 | AH39: 0 | AI39: 0 | AJ39: 0.60000002 | AK39: 0.71428573 | AL39: 0 | AM39: 0.80000001 | AN39: 0.83333331
A40: 12 | B40: ARI protocol applied | C40: 0.4376867 | D40: 0.4365079 | E40: 0 | F40: 1 | G40: 0.5 | H40: 0.75 | I40: 0.66666669 | J40: 0.69999999 | K40: 0 | L40: 0.25 | M40: 0 | N40: 0.5 | O40: 0.69999999 | P40: 0 | Q40: 0.33333334 | R40: 0.1 | S40: 0.5 | T40: 0.44444445 | U40: 0.375 | V40: 0.33333334 | W40: 1 | X40: 1 | Y40: 0.42857143 | Z40: 1 | AA40: 0.75 | AB40: 0.66666669 | AC40: 0.5 | AD40: 0.25 | AE40: 0.16666667 | AF40: 1 | AG40: 0 | AH40: 0 | AI40: 0.33333334 | AJ40: 0.2 | AK40: 0 | AL40: 0 | AM40: 0.60000002 | AN40: 0.83333331
...

Sheet Annex1b-Structural_FAC
E1: QQM - Structural Indicators - HER2 R1 - January to March 2024 Domain 1: General management (14 points) | T1: QQM - Structural Indicators - HER2 R1 - January to March 2024 Domain 2: Hygiene (34 points) | AJ1: QQM - Structural Indicators - HER2 R1 - January to March 2024 Domain 3: OPD/Curative Consultations (44 points) | BN1: QQM - Structural Indicators - HER2 R1 - January to March 2024 Domain 4: Family planning (23 points) | CA1: QQM - Structural Indicators - HER2 R1 - January to March 2024 Domain 5: Laboratory (15 points, NA for some BHC) | CQ1: QQM - Structural Indicators - HER2 R1 - January to March 2024 Domain 6: Essential Drugs Management (52 points) | DC1: QQM - Structural Indicators - HER2 R1 - January to March 2024 Domain 7: Availability of tracer drugs (92 points) | DK1: QQM - Structural Indicators - HER2 R1 - January to March 2024 Domain 8: Maternity (29 points) | EB1: QQM - Structural Indicators - HER2 R1 - January to March 2024 Domain 9: EPI (27 points) | EW1: QQM - Structural Indicators - HER2 R1 - January to March 2024 Domain 10: Antenatal care (13 points) | FG1: QQM - Structural Indicators - HER2 R1 - January to March 2024 Overall score (BHC: 330 points; CHC/DH: 345 points)
A2: Province | B2: Service Provider | C2: Facility type | D2: Facility ID | E2: Presence of map of health facility catchment area | F2: Proper filing system | G2: Staff duty roster up-to-date and visible | H2: Technical meetings conducted | I2: Standard referral sheets available | J2: Availability of dedicated mobile phone for communication between health facility and general hospital | K2: HMIS reports (sent to SP offices and MoPH) | L2: HMIS reports (assessed concerning priority problems) | M2: Health Shura meetings | N2: Domain 1 score | P2: Province | Q2: Service Provider | R2: Facility type | S2: Facility ID | T2: Fence health facility available and well-maintained | U2: Garbage bin available | V2: Latrines/toilets are well maintained | W2: Showers are well maintained | X2: Waste pits are well maintained | Y2: Courtyard clean | Z2: Sterilization according to norms | AA2: Hygienic condicitions assured during wound dressing and injections | AB2: Disposal of Health Care Waste | AC2: COVID-19 prevention | AD2: Domain 2 score | AF2: Province | AG2: Service Provider | AH2: Facility type | AI2: Facility ID | AJ2: Good conditions in waiting area | AK2: Drugs which are available free of charge displayed to the public | AL2: Waiting card (or token) system with numbers | AM2: Consultation room in good condition | AN2: Consultation (emergency) room has 24/7 light | AO2: Consultations done by skilled staff | AP2: Consulting staff well-dressed | AQ2: Correct numbering of registers | AR2: Service availability 24/7 | AS2: Malaria protocol | AT2: ARI WHO flow diagram | AU2: ARI protocol applied | AV2: Diarrhea WHO protocol | AW2: Diarrhea protocol applied | AX2: Proportion of cosultations treated with antibiotics <30% | AY2: Afghanistan National Standard Treatment guidelines primary level available in consultation rooms | AZ2: Knowledge of tuberculosis presumptive case screening | BA2: Stethoscope and BP machine available and functional | BB2: Thermometer available and functional | BC2: Otoscope available and functional | BD2: Examination table with padding available | BE2: Weighing scale available and functional | BF2: Integrated Management of Childhood Illnesses strategy is applied | BG2: Determination of nutritional status (weight, upper arm circumference, height) | BH2: Domain 3 score | BJ2: Province | BK2: Service Provider | BL2: Facility type | BM2: Facility ID | BN2: Qualified staff trained in Family Planning | BO2: Confidentiality in consultancy room assured | BP2: Family planning methods available and visible | BQ2: IUD available and staff trained to use it | BR2: Implant method available and staff trained to use it | BS2: Post Partum and Post Abortion Family Planning Services available | BT2: Family planning individual cards | BU2: Domain 4 score | BW2: Province | BX2: Service Provider | BY2: Facility type | BZ2: Facility ID | CA2: Medical Laboratory technician available | CB2: Laboratory is open every day of the week | CC2: List of laboratory examinations visible | CD2: Results recorded correctly in laboratory register and match with results in inpatient sheets or OPD examination cards | CE2: Availability of parasited demonstrations | CF2: Microscope available | CG2: Centrifuge available and functional | CH2: Waste evacuation correctly carried out | CI2: Personnel adequately washes dirty pipettes in containers with disinfectant | CJ2: Laboratory equipment for testing for Tuberculosis | CK2: Domain 5 score | CM2: Province | CN2: Service Provider | CO2: Facility type | CP2: Facility ID | CQ2: Health facility has separate rooms for dispensary and main stocks | CR2: Health facility receives drugs ordered timely and as ordered from the SP central pharmacy | CS2: Supply management knowledge | CT2: Drugs sorted correctly | CU2: Absence of out of date drugs or drugs with unreadable labels | CV2: Good Dispensing Practices | CW2: Domain 6 score | CY2: Province | CZ2: Service Provider | DA2: Facility type | DB2: Facility ID | DC2: Availability of tracer drugs (MAC*2) | DD2: Percentage of MAC correctly calculated (out of 5) | DE2: Domain 7 score | DG2: Province | DH2: Service Provider | DI2: Facility type | DJ2: Facility ID | DK2: Sufficient water with soap and liquid antiseptics in delivery room | DL2: Light and heat 24 hours in delivery room | DM2: Waste from maternity correctly handled | DN2: Delivery room well maintained | DO2: Availability and use of the partograph | DP2: Deliveries performed by skilled personnel | DQ2: Availability of scales for weight/length, and obstrectical stethoscope | DR2: Availability of at least one episiotomy/perineal repair box | DS2: Delivery table in good state | DT2: Available equipment for care of the newborn | DU2: Adequate in-patient rooms | DV2: Domain 8 score | DX2: Province | DY2: Service Provider | DZ2: Facility type | EA2: Facility ID | EB2: Personnel calculates correctly target for fully vaccinated children | EC2: EPI fridge | ED2: Chemical temperature present | EE2: Appropriate storage of vaccines | EF2: Appropriate stock of vaccines | EG2: Cold Chain maintenance | EH2: Cold Boxes and Cold packs | EI2: Syringes available | EJ2: Waste collection availability of safe disposal box | EK2: Stock of U5 growth cards available | EL2: Child immunization register well maintained & Montly monitoring chart well filled and updated | EM2: Adequate conditions in immunization waiting area | EN2: Patients receive numbered waiting tokens according to their arrival | EO2: Baby weighing scale available and in working condition | EP2: EPI and Vit A IEC/SBCC materials | EQ2: Domain 9 score | ES2: Province | ET2: Service Provider | EU2: Facility type | EV2: Facility ID | EW2: Presence of a plan which contains convincing strategies to effectively conduct ANC for all pregnant women in catchment area | EX2: Essential equipment present | EY2: ANC form available and well filled in: last five forms verified | EZ2: ANC form shows the administration of Ferrous Sulphate/Folic Acid (for at least 30 days) and Mebendazole (once in second trimester) (for the last five forms above). | FA2: MCH-HB cards available, at least thirty | FB2: ANC register available and well filled | FC2: ANC conducted by qualified personnel | FD2: Individual IEC/BCC | FE2: Domain 10 score
A3: Badakhshan | B3: AKDN | C3: CHC | D3: 401 | E3: 0 | F3: 2.5 | G3: 1 | H3: 3 | I3: 1 | J3: 0 | K3: 1 | L3: 0 | M3: 2 | N3: 0.75 | P3: Badakhshan | Q3: AKDN | R3: CHC | S3: 401 | T3: 1 | U3: 0 | V3: 0.5 | W3: 0.5 | X3: 0 | Y3: 1 | Z3: 3 | AA3: 0 | AB3: 0 | AC3: 0 | AD3: 0.1764706 | AF3: Badakhshan | AG3: AKDN | AH3: CHC | AI3: 401 | AJ3: 1 | AK3: 1 | AL3: 1 | AM3: 0 | AN3: 1 | AO3: 0 | AP3: 2 | AQ3: 1 | AR3: 2 | AS3: 2 | AT3: 0 | AU3: 1 | AV3: 2 | AW3: 1 | AX3: 0 | AY3: 1 | AZ3: 2 | BA3: 0.5 | BB3: 0.5 | BC3: 0.5 | BD3: 1 | BE3: 0.5 | BF3: 0 | BG3: 8 | BH3: 0.6590909 | BJ3: Badakhshan | BK3: AKDN | BL3: CHC | BM3: 401 | BN3: 1 | BO3: 4 | BP3: 7 | BQ3: 3 | BR3: 3 | BS3: 3 | BT3: 2 | BU3: 1 | BW3: Badakhshan | BX3: AKDN | BY3: CHC | BZ3: 401 | CA3: 1 | CB3: 0 | CC3: 1 | CD3: 2 | CE3: 1 | CF3: 2 | CG3: 1 | CH3: 0 | CI3: 1 | CJ3: 3 | CK3: 0.8 | CM3: Badakhshan | CN3: AKDN | CO3: CHC | CP3: 401 | CQ3: 8 | CR3: 0 | CS3: 12 | CT3: 4 | CU3: 2 | CV3: 8 | CW3: 0.6538461 | CY3: Badakhshan | CZ3: AKDN | DA3: CHC | DB3: 401 | DC3: 0 | DD3: 0 | DE3: 0 | DG3: Badakhshan | DH3: AKDN | DI3: CHC | DJ3: 401 | DK3: 0 | DL3: 1 | DM3: 0 | DN3: 3 | DO3: 2 | DP3: 3 | DQ3: 8 | DR3: 1 | DS3: 1 | DT3: 2 | DU3: 0 | DV3: 0.7241379 | DX3: Badakhshan | DY3: AKDN | DZ3: CHC | EA3: 401 | EB3: 0 | EC3: 8 | ED3: 0 | EE3: 0 | EF3: 0 | EG3: 1 | EH3: 0 | EI3: 1 | EJ3: 1 | EK3: 1 | EL3: 1 | EM3: 1 | EN3: 1 | EO3: 1 | EP3: 1 | EQ3: 0.6296296 | ES3: Badakhshan | ET3: AKDN | EU3: CHC | EV3: 401 | EW3: 0.5 | EX3: 0 | EY3: 0 | EZ3: 0 | FA3: 0.5 | FB3: 0 | FC3: 2 | FD3: 0 | FE3: 0.2307692 | FG3: 0.4533528
